Workbook

Sheet Platform_Summary
A1: Platform | B1: Claude_Source_Records | C1: GPT_Source_Records | D1: CodeX_Source_Records | E1: TestBatch_Source_Records | F1: Total_Source_Records | G1: Reconciled_Datasets | H1: Duplicate_Records_Removed | I1: Datasets_Also_Found_on_Other_Platforms | J1: Platform_Unique_Datasets | K1: Original_Datasets | L1: Derived_Datasets | M1: Compiled_Datasets | N1: Repository_Mirrors | O1: Datasets_With_Publication | P1: Datasets_With_Image_Count | Q1: Datasets_With_Labels | R1: Datasets_With_Annotation_Information | S1: Datasets_With_AI_Task | T1: Datasets_With_AI_Method | U1: Accessible_Datasets | V1: Inaccessible_or_Broken_Links | W1: Excluded_Candidates_Logged | X1: Main_Data_Types | Y1: Main_Annotation_Styles | Z1: Main_AI_Tasks | AA1: Main_Strengths | AB1: Main_Limitations | AC1: Notes
A2: ALL SIX PLATFORMS - TOTAL (deduplicated; each reconciled dataset counted once) | B2: 147 | C2: 73 | D2: 13 | E2: 34 | F2: 267 | G2: 177 | H2: 90 | I2: 20 | J2: 156 | K2: 148 | L2: 18 | M2: 11 | N2: 20 | O2: 89 | P2: 109 | Q2: 173 | R2: 167 | S2: 172 | T2: 24 | U2: 162 | V2: 7 | W2: 574 | X2: NR | Y2: NR | Z2: NR | AA2: NR | AB2: NR | AC2: OVERALL SUMMARY - Total source records across the six platforms: 267. Total reconciled datasets after cross-tool and cross-platform deduplication: 177. Total duplicate source records merged/removed: 90. Datasets appearing on multiple platforms: 20. Datasets on exactly one platform: 156. Datasets on none of the six platforms (institutional/arXiv-only hosting): 1. Counts are static values computed from the source workbooks at build time (2026-08-10). A dataset hosted on several platforms is counted once in this TOTAL row but appears in each relevant platform row below, so platform-row Reconciled_Datasets sum to more than 177.
A3: GitHub | B3: 26 | C3: 17 | D3: 0 | E3: 34 | F3: 77 | G3: 46 | H3: 24 | I3: 10 | J3: 36 | K3: 44 | L3: 1 | M3: 1 | N3: 10 | O3: 39 | P3: 32 | Q3: 46 | R3: 43 | S3: 45 | T3: 14 | U3: 38 | V3: 4 | W3: 253 | X3: Research image datasets (RGB, UAV, infrared/RGB-T, stereo); repository-hosted archives and external-drive links | Y3: Bounding boxes (VOC/YOLO); pixel-level segmentation masks; classification folders | Z3: Object detection; semantic segmentation; crack detection; classification; PCI estimation | AA3: Hosts most canonical academic benchmarks (RDD family, CRACK500, GAPs384, EdmCrack600, UAPD, CQU-BPDD); rich READMEs with publications; free direct access | AB3: Data often stored on external drives (Google Drive/Baidu) with unverified liveness; several announced-but-unreleased datasets (Pending); repository search recall unstable; licenses frequently unstated | AC3: Three GitHub batches exist: Claude_Github_001 and ChatGPT_Github_001 (both 2026-08-06) plus Github_Github_Test (2026-08-01, tool attribution UNK). The test batch contributes 13 datasets found by no dated batch (classical benchmarks such as CrackForest, CrackTree260, CRKWH100, CrackLS315, DeepCrack-537).
A4: Data.gov | B4: 1 | C4: 2 | D4: 0 | E4: 0 | F4: 3 | G4: 2 | H4: 1 | I4: 0 | J4: 2 | K4: 2 | L4: 0 | M4: 0 | N4: 0 | O4: 2 | P4: 0 | Q4: 1 | R4: 2 | S4: 0 | T4: 0 | U4: 1 | V4: 0 | W4: 36 | X4: Agency program databases (LTPP) with section-level distress imagery; predominantly tabular/GIS records otherwise | Y4: Section-level distress type/severity/extent per LTPP Distress Identification Manual; no image-space annotations | Z4: Pavement condition/IRI/PCI prediction from structured data; imagery requires pairing work for CV use | AA4: Authoritative, QA-documented federal data (LTPP) with multimodal companions (traffic, climate, FWD); long temporal coverage since 1990s | AB4: Only one image-bearing dataset met the modality rule (LTPP); catalog dominated by tabular PCI/GIS records; image counts/resolutions unreported; bulk-download authorization unclear | AC4: Both tools converged on LTPP as the single eligible record; GPT additionally kept the Non-LTPP access collection Pending. Both tools excluded the same companion catalog records (LTPP Map/Library/0549d harvest duplicate) and 30+ tabular PCI/GIS records (Montgomery County PCI, NYC Street Pavement Rating, HPMS, Chicago potholes, Sioux Falls).
A5: Mendeley Data | B5: 39 | C5: 12 | D5: 4 | E5: 0 | F5: 55 | G5: 43 | H5: 13 | I5: 10 | J5: 33 | K5: 39 | L5: 3 | M5: 1 | N5: 10 | O5: 14 | P5: 29 | Q5: 42 | R5: 40 | S5: 42 | T5: 5 | U5: 43 | V5: 1 | W5: 63 | X5: Author-deposited research image datasets with DOIs; several data-article-backed deposits | Y5: Bounding boxes; segmentation masks; classification folders; oriented boxes (CoCG) | Z5: Object detection; classification; semantic segmentation | AA5: Largest pool of DOI-minted original deposits (RDD2020, PaveDistress, HighRPD, Attain, SUT-Crack); frequent Data-in-Brief articles; consistent CC-BY licensing | AB5: No file manifests exposed to non-interactive review (counts unverifiable); country/collection metadata often absent; duplicate deposits of the same dataset occur (MWPD) | AC5: Counts follow the standard platform order and are computed after cross-platform deduplication; a multi-platform dataset is counted in each platform it appears on.
A6: Hugging Face | B6: 8 | C6: 17 | D6: 0 | E6: 0 | F6: 25 | G6: 21 | H6: 3 | I6: 4 | J6: 17 | K6: 11 | L6: 6 | M6: 4 | N6: 4 | O6: 18 | P6: 16 | Q6: 21 | R6: 21 | S6: 21 | T6: 3 | U6: 20 | V6: 0 | W6: 30 | X6: Community re-uploads and Roboflow exports; a few original large sets (PaveBench, CrackBlock600K) | Y6: YOLO/COCO conversions; classification folders; instance segmentation | Z6: Object detection; classification; semantic/instance segmentation | AA6: Easy programmatic access (load_dataset/viewer); hosts reformatted versions of canonical sets (SVRDD_YOLO, CQU-BPDD) | AB6: Mostly re-uploads rather than canonical sources; collection context (country, sensor, dates) rarely documented; native search not reproducible non-interactively; licenses often missing | AC6: Counts follow the standard platform order and are computed after cross-platform deduplication; a multi-platform dataset is counted in each platform it appears on.
A7: Zenodo | B7: 30 | C7: 9 | D7: 6 | E7: 0 | F7: 45 | G7: 35 | H7: 11 | I7: 6 | J7: 29 | K7: 32 | L7: 2 | M7: 1 | N7: 6 | O7: 14 | P7: 21 | Q7: 34 | R7: 34 | S7: 35 | T7: 5 | U7: 31 | V7: 2 | W7: 134 | X7: DOI-minted research deposits incl. multimodal (infrared, MLS, GPR) and regional datasets | Y7: Bounding boxes; segmentation masks; classification folders; point-cloud labels | Z7: Object detection; classification; semantic/instance segmentation; multimodal fusion; severity classification | AA7: Reproducible API search; versioned DOIs; strong regional diversity (Iraq, Ecuador, Bangladesh, Morocco, Brazil, Poland, Finland); infrared thermography series | AB7: Image counts/geography frequently absent from deposits; many very recent records with no reuse evidence; some restricted/metadata-only records (CAMBER series) | AC7: Counts follow the standard platform order and are computed after cross-platform deduplication; a multi-platform dataset is counted in each platform it appears on.
A8: Kaggle | B8: 43 | C8: 16 | D8: 3 | E8: 0 | F8: 62 | G8: 50 | H8: 12 | I8: 11 | J8: 39 | K8: 39 | L8: 6 | M8: 5 | N8: 11 | O8: 19 | P8: 26 | Q8: 49 | R8: 47 | S8: 49 | T8: 5 | U8: 49 | V8: 1 | W8: 58 | X8: Uploader-driven mirrors and derived compilations; some original community datasets | Y8: Bounding boxes (YOLO); instance segmentation; classification folders | Z8: Object detection; classification; instance segmentation; severity classification | AA8: Largest raw record volume; convenient packaging; version history via API; several datasets not found elsewhere (PVS, RAD, STU_CamCrack792) | AB8: Mostly re-uploads of Zenodo/Mendeley/Roboflow data with uploader-set licenses; registration required for download; data cards lack schema (high NR density); no citation counts; empty data cards on several records | AC8: Highest duplication pressure of the six platforms: RDD2022, CRACK500, SDNET2018, RTK, UAV-PDD2023 (as UAV-SEG-2025), Concrete & Pavement Crack, MWPD, Road Issues, Drone-based Inspection and the Arcioni road-damage dataset all also exist on other platforms. Claude verified records via the unauthenticated Kaggle API; GPT via rendered pages.
A9: Other (not hosted on any of the six platforms) | B9: NR | C9: NR | D9: NR | E9: NR | F9: 1 | G9: 1 | H9: NR | I9: NR | J9: NR | K9: NR | L9: NR | M9: NR | N9: NR | O9: NR | P9: NR | Q9: NR | R9: NR | S9: NR | T9: NR | U9: NR | V9: NR | W9: NR | X9: NR | Y9: NR | Z9: NR | AA9: NR | AB9: NR | AC9: Datasets surfaced by the searches but hosted outside the six platforms: AEL Road Crack Dataset. Retained for traceability; excluded from Platform_Unique.

Sheet AI_Tool_Summary
A1: AI_Tool | B1: Total_Source_Records | C1: Reconciled_Datasets_Identified | D1: Datasets_Also_Identified_by_Other_AI_Tool | E1: AI_Tool_Unique_Datasets | F1: GitHub_Datasets | G1: DataGov_Datasets | H1: Mendeley_Datasets | I1: HuggingFace_Datasets | J1: Zenodo_Datasets | K1: Kaggle_Datasets | L1: Datasets_With_Image_Count | M1: Datasets_With_Label_Information | N1: Datasets_With_Annotation_Information | O1: Datasets_With_AI_Task | P1: Datasets_With_AI_Method | Q1: Datasets_With_Publication | R1: Datasets_With_Access_Status | S1: Datasets_With_License | T1: Include_Decisions | U1: Pending_Decisions | V1: Exclude_Decisions | W1: Main_Search_Strengths | X1: Main_Search_Limitations | Y1: Main_Metadata_Strengths | Z1: Main_Metadata_Gaps | AA1: Notes
A2: ALL TOOLS - RECONCILED TOTAL | B2: 267 | C2: 177 | D2: 34 | E2: NR | F2: NR | G2: NR | H2: NR | I2: NR | J2: NR | K2: NR | L2: NR | M2: NR | N2: NR | O2: NR | P2: NR | Q2: NR | R2: NR | S2: NR | T2: NR | U2: NR | V2: NR | W2: NR | X2: NR | Y2: NR | Z2: NR | AA2: OVERALL SUMMARY - Total reconciled datasets: 177. Identified by BOTH Claude and GPT: 34. Only by Claude (not GPT): 98. Only by GPT (not Claude): 31. CodeX-involved: 13 (CodeX-only: 1). Unattributed GitHub test batch only: 13. MAIN REASONS FOR CLAUDE-GPT DIFFERENCES: (1) recall asymmetry by platform - Claude ran API-level exhaustive searches on Kaggle/Mendeley/Zenodo (43/39/30 records vs GPT 16/12/9), while GPT covered Hugging Face far better (17 vs 8) because Claude could not access HF native search non-interactively; (2) different canonical-source policies - GPT GitHub batch excluded the RDD2022 Kaggle mirror and RDD2020 HF mirror as duplicates that Claude Kaggle retained (both reconcile here); (3) screening-strictness differences - Claude excluded CHDyshli/PavementCrackDetection as NOT_DATASET where GPT included it (GH-005); GPT HF batch excluded manot/pothole-segmentation2 as a duplicate mirror where Claude included it (DSHF-008); (4) date/venue coverage - GPT found older/institutional sets (MIIA, FIND, Weakly-Supervised Crack), Claude found more 2025-2026 deposits. IMPORTANT INCLUDE-VS-EXCLUDE DISAGREEMENTS: CHDyshli highway crack dataset (Claude excluded, GPT included); manot/pothole-segmentation2 (GPT excluded as mirror, Claude included); RDD2022 Kaggle mirror and RDD2020 HF mirror (GPT excluded as duplicates, Claude/others retained - merged into one reconciled record each here); LTPP companion catalog records (both tools excluded consistently as duplicates). Include/exclude and status conflicts on shared datasets are flagged per row in All_Datasets (Include_Exclude_Conflict = Y). No AI-readiness scores are used or reported anywhere in this workbook.
A3: Claude | B3: 147 | C3: 132 | D3: 41 | E3: 89 | F3: 27 | G3: 1 | H3: 39 | I3: 10 | J3: 30 | K3: 44 | L3: 75 | M3: 128 | N3: 121 | O3: 127 | P3: 7 | Q3: 49 | R3: 130 | S3: 108 | T3: 133 | U3: 14 | V3: 443 | W3: API-driven, exhaustively paginated searches (GitHub REST, Zenodo API, DataCite index for Mendeley, Kaggle public API); largest record volume on Kaggle (43), Mendeley (39) and Zenodo (30); systematic dedup and series collapsing (CAMBER 67-to-1); access verified at data-file level (HTTP tests); every excluded candidate logged (445 exclusion entries). | X3: Hugging Face native search inaccessible non-interactively (only 8 records; missed PaveBench, CrackBlock600K-HF, Unified Road Defect, BLACrack, RSCD); did not surface SVRDD on Zenodo or several GPT-found Zenodo/Mendeley records (FIND, South Africa binary crack, Cracks-and-Potholes-in-Road-Images, Pothole Videos, PathCare); GitHub batch excluded some data-bearing repos as NOT_DATASET (e.g., CHDyshli) that GPT included. | Y3: High completeness on acquisition platform, distress taxonomy, annotation method/QC, license and evidence locators; explicit no-inference policy with NR/UNK codes; conflicts and unresolved issues documented per record. | Z3: Publications_Using_Dataset_Count NR throughout; no benchmark models/metrics recorded (per no-fabrication rule); country frequently NR where only depositor affiliation was available; Kaggle records carry Registration access (platform-level) rather than per-file verification. | AA3: Claude batches reviewed: DataGov, Github, Huggingface, Kaggle, Mendeley, Zendo (each _001). Reviewers: Tianzhi He (DataGov/GitHub/HF), Mo Hu (Kaggle/Mendeley/Zenodo). Search dates 2026-08-03 to 2026-08-06.
A4: GPT (ChatGPT) | B4: 73 | C4: 65 | D4: 34 | E4: 25 | F4: 16 | G4: 2 | H4: 16 | I4: 16 | J4: 12 | K4: 16 | L4: 43 | M4: 64 | N4: 65 | O4: 63 | P4: 19 | Q4: 42 | R4: 63 | S4: 31 | T4: 68 | U4: 5 | V4: 97 | W4: Better Hugging Face coverage (17 records incl. PaveBench, CrackBlock600K, Unified Road Defect, RSCD-1million, BLACrack); found several Zenodo/Mendeley datasets Claude missed (SVRDD, FIND, South African binary crack, Weakly-Supervised Crack, Pothole Videos, PathCare, Cracks-and-Potholes-in-Road-Images, MIIA); GitHub batch actively resolved canonical sources (figshare/Mendeley links) and excluded mirrors explicitly. | X4: Much lower recall on Kaggle (16 vs 43), Mendeley (12 vs 39) and Zenodo (9 vs 30) than Claude; no stable result totals (Results_Returned frequently NR); Zenodo HTTP 429 throttling forced use of indexed page text; relative dates not converted to YYYY-MM; some batches completed 2 days after protocol search date. | Y4: Richer publication linking on GitHub/HF records (multiple DOIs per record); consistent controlled-value formatting on HF batch; canonical-source resolution notes (mirror provenance). | Z4: License and image counts NR on many Zenodo/Mendeley records where Claude found values; acquisition detail often generic (platform NR); several records rely on indexed snapshots rather than live pages (INACC risk). | AA4: GPT batches reviewed: ChatGPT_Github_001, ChatGPT_Huggingface_001, ChatGPT_DataGov_001 (file ChatGP_DataGov_001), GPT_Kaggle_001, GPT_Mendeley_001, GPT_Zenodo_001. Search dates 2026-08-03 to 2026-08-06.
A5: CodeX (supplementary third tool; Kaggle/Mendeley/Zenodo batches only) | B5: 13 | C5: 13 | D5: 12 | E5: 1 | F5: 2 | G5: 0 | H5: 4 | I5: 0 | J5: 6 | K5: 4 | L5: 11 | M5: 13 | N5: 13 | O5: 13 | P5: 3 | Q5: 4 | R5: 13 | S5: 11 | T5: 13 | U5: 0 | V5: 9 | W5: Precise verification of retained records (full citations in DOI fields); found CAMBER sibling record and CDAC-DAI details missed by GPT. | X5: Very low recall: only 13 records across three platforms (Kaggle 3, Mendeley 4, Zenodo 6); no GitHub, Data.gov or Hugging Face batches; Zenodo query Q03 returned INACC. | Y5: Accurate counts where reported (e.g., IRT crack dataset 369 images; UAV-SEG 2,426). | Z5: Most geography/sensor/QC fields NR; no publication enumeration. | AA5: CodeX contributed no datasets that reconcile outside Claude/GPT coverage except sibling detail; 1 dataset(s) unique to CodeX. Treated as supplementary third tool; not part of the primary Claude-vs-GPT comparison.
A6: Github_Github_Test batch (tool attribution UNK; GitHub only; search 2026-08-01) | B6: 34 | C6: 34 | D6: 21 | E6: 13 | F6: 30 | G6: 0 | H6: 6 | I6: 1 | J6: 2 | K6: 3 | L6: 26 | M6: 34 | N6: 34 | O6: 34 | P6: 2 | Q6: 34 | R6: 31 | S6: 2 | T6: 27 | U6: 7 | V6: 25 | W6: Broadest GitHub sweep of classical crack benchmarks: unique records for CrackForest (CFD), CrackTree260, CRKWH100, CrackLS315, DeepCrack-537, AEL, RCD-IIUM, Stereo Pothole Datasets, SoV, CrackSeg9k, R2S100K, jaygala24 pothole set. | X6: Tool attribution not recorded in the file (README Review_Batch_ID = Github_001, reviewer Tianzhi He, search 2026-08-01, before the dated Claude/GPT GitHub batches); treated as an unattributed test batch and EXCLUDED from Claude-vs-GPT unique/overlap statistics. | Y6: Good acquisition detail (camera systems) and publication links for classical benchmarks. | Z6: Licenses almost entirely NR; many Pending records; several arXiv-only access routes. | AA6: 13 reconciled dataset(s) rest ONLY on this batch and carry AI_Tools_Identifying_Dataset = GitHub_Test_Batch (tool UNK).

Sheet All_Datasets
A1: Reconciled_Dataset_ID | B1: Standardized_Dataset_Name | C1: Alternate_Dataset_Names | D1: Dataset_Version | E1: Match_Classification | F1: Match_Confidence | G1: Match_Evidence | H1: AI_Tools_Identifying_Dataset | I1: Data_Platforms | J1: Appears_on_Multiple_Platforms | K1: Platform_Relationship | L1: Preferred_Dataset_URL | M1: GitHub_URL | N1: DataGov_URL | O1: Mendeley_Data_URL | P1: HuggingFace_URL | Q1: Zenodo_URL | R1: Kaggle_URL | S1: Other_Dataset_URLs | T1: DOI_or_Persistent_ID | U1: Related_Publication | V1: Publication_Citation | W1: Publication_DOI | X1: Publication_URL | Y1: Publication_Year | Z1: Peer_Reviewed_Publication | AA1: Publication_Dataset_Relationship | AB1: Dataset_Scale_Type | AC1: Number_of_Images | AD1: Number_of_Videos | AE1: Number_of_Frames | AF1: Number_of_Samples | AG1: Number_of_Road_Segments | AH1: Number_of_Annotated_Instances | AI1: Number_of_Classes | AJ1: Training_Set_Size | AK1: Validation_Set_Size | AL1: Testing_Set_Size | AM1: Dataset_Storage_Size | AN1: Image_Resolution | AO1: Video_Resolution | AP1: Country | AQ1: State_or_Province | AR1: City_or_Region | AS1: Geographic_Coverage | AT1: Temporal_Coverage | AU1: Acquisition_Platform | AV1: Vehicle_Type | AW1: Camera_Type | AX1: Camera_Position | AY1: Smartphone_Data | AZ1: Drone_or_Aerial_Data | BA1: CAV_AV_ADAS_Data | BB1: LiDAR_Availability | BC1: GPS_or_Geolocation | BD1: Other_Sensors | BE1: Weather_Conditions | BF1: Lighting_Conditions | BG1: Traffic_Conditions | BH1: Distress_Types | BI1: Pavement_Condition_Labels | BJ1: Label_Taxonomy | BK1: Number_of_Label_Classes | BL1: Annotation_Task_Type | BM1: Annotation_Style | BN1: Annotation_Format | BO1: Annotation_File_Format | BP1: Classification_Labels | BQ1: Bounding_Boxes | BR1: Segmentation_Masks | BS1: Polygons | BT1: Keypoints | BU1: Severity_Labels | BV1: PCI_Availability | BW1: IRI_Availability | BX1: Maintenance_Record_Availability | BY1: Annotation_Source | BZ1: Annotation_Quality_Control | CA1: Class_Balance | CB1: Unlabeled_Data_Availability | CC1: Reported_AI_Tasks | CD1: Reported_AI_Methods | CE1: Reported_Models_or_Architectures | CF1: AI_Task_Evidence | CG1: Evaluation_Metrics | CH1: Benchmark_Results | CI1: Screening_Decision | CJ1: Access_Status | CK1: License | CL1: Registration_Requirement | CM1: Download_Requirement | CN1: Documentation_Quality | CO1: Label_Documentation_Quality | CP1: Broken_or_Inaccessible_Link | CQ1: Key_Limitations | CR1: Original_Derived_or_Compiled | CS1: Repository_Mirror | CT1: Different_Version | CU1: Derived_or_Reformatted | CV1: Parent_Dataset | CW1: Related_Datasets | CX1: Source_Filenames | CY1: Source_Record_IDs | CZ1: Claude_Reported_Values_Conflict | DA1: GPT_Reported_Values_Conflict | DB1: Scale_Conflicts | DC1: Label_Conflicts | DD1: Platform_Conflicts | DE1: Other_Metadata_Conflicts | DF1: Include_Exclude_Conflict | DG1: Reconciliation_Notes | DH1: Evidence_Locator | DI1: Confidence_Level | DJ1: Verification_Priority | DK1: Recommended_Action | DL1: AIR_Accessibility_0_5 | DM1: AIR_Annotation_Quality_0_5 | DN1: AIR_Documentation_0_5 | DO1: AIR_Scale_0_5 | DP1: AIR_Diversity_0_5 | DQ1: AIR_Sensor_Metadata_0_5 | DR1: AIR_Agency_Ground_Truth_0_5 | DS1: AIR_Overall_Default_Weights_0_100 | DT1: AIR_Score_Basis | DU1: AIR_Scored_Source_Records | DV1: V3_AI_Grade | DW1: V3_Human_Grade | DX1: V3_AI_Confirmed_100 | DY1: V3_Human_Confirmed_100 | DZ1: V3_AI_Upper_100 | EA1: V3_Human_Upper_100 | EB1: V3_AI_Resolved_Pct | EC1: V3_Human_Resolved_Pct | ED1: V3_AI_Access_5 | EE1: V3_Human_Access_5 | EF1: V3_AI_Label_Quality_5 | EG1: V3_Human_Label_Quality_5 | EH1: V3_AI_Documentation_5 | EI1: V3_Human_Documentation_5 | EJ1: V3_AI_Sample_Size_5 | EK1: V3_Human_Sample_Size_5 | EL1: V3_AI_Domain_Fit_5 | EM1: V3_Human_Domain_Fit_5 | EN1: V3_AI_Sensor_Details_5 | EO1: V3_Human_Sensor_Details_5 | EP1: V3_AI_Test_Readiness_5 | EQ1: V3_Human_Test_Readiness_5 | ER1: V3_AI_Engineering_Value_5 | ES1: V3_Human_Engineering_Value_5 | ET1: V3_AI_Eligibility | EU1: V3_Human_Eligibility | EV1: V3_Human_Completion_Pct | EW1: V3_Human_minus_AI_Confirmed | EX1: V3_State_Agreement_Pct | EY1: V3_AI_Evidence_Note | EZ1: V3_Human_Evidence_Note | FA1: V3_AI_Source_URL | FB1: V3_Human_Source_URL | FC1: View_Orientation | FD1: View_Top_Down_Nadir | FE1: View_Forward_Facing_Oblique | FF1: View_Other | FG1: View_Platform_Mount | FH1: View_Evidence_Quote | FI1: View_Evidence_Source | FJ1: View_Evidence_URL | FK1: View_Label_Confidence | FL1: View_Verification | FM1: View_Label_Notes
A2: DS-001 | B2: Asphalt Pavement Crack Data (class-foldered grayscale images) | C2: NA | D2: v1 | E2: Independent Dataset | F2: NA (single source record) | G2: Single source record; no matching record found in any other file after cross-file and cross-platform comparison. | H2: Claude | I2: GitHub | J2: N | K2: NA (single platform) | L2: https://github.com/summoners29/Asphalt-Pavement-Crack-Data | M2: https://github.com/summoners29/Asphalt-Pavement-Crack-Data | N2: NA | O2: NA | P2: NA | Q2: NA | R2: NA | S2: NA | T2: NR | U2: N | V2: NR | W2: NR | X2: NR | Y2: NR | Z2: NA | AA2: NA | AB2: NR | AC2: NR | AD2: NR | AE2: NR | AF2: NR | AG2: NR | AH2: NR | AI2: NR | AJ2: NR | AK2: NR | AL2: NR | AM2: NR | AN2: NR | AO2: NR | AP2: NR | AQ2: NR | AR2: NR | AS2: Road environment: Asphalt pavements | AT2: NR | AU2: NR | AV2: NR | AW2: NR | AX2: NR | AY2: NR | AZ2: NR | BA2: NR | BB2: N | BC2: N | BD2: NR | BE2: NR | BF2: NR | BG2: NR | BH2: Alligator crack (additional classes per folder structure UNK) | BI2: NR | BJ2: Folder-level class labels (e.g., Alligator) | BK2: NR | BL2: Image classification | BM2: Image classification | BN2: Class-folder structure (grayscale jpg) | BO2: NR | BP2: Y | BQ2: NR | BR2: NR | BS2: NR | BT2: NR | BU2: NR | BV2: N | BW2: N | BX2: N | BY2: NR | BZ2: NR | CA2: NR | CB2: NR | CC2: Classification | CD2: NR | CE2: NR | CF2: Reported on the source record/data card or associated publication (see Evidence_Locator) | CG2: NR | CH2: NR | CI2: Include-Supplementary | CJ2: Direct_Download | CK2: NR | CL2: N | CM2: Direct_Download | CN2: NR | CO2: NR | CP2: N | CQ2: No README, no counts, no license or provenance; images stored directly in repository | CR2: Original | CS2: N | CT2: N | CU2: N | CV2: NA | CW2: NA | CX2: Claude_Github_001.xlsx | CY2: Claude_Github_001:GH-DS-022 | CZ2: N | DA2: NA | DB2: None | DC2: None | DD2: None | DE2: None | DF2: N | DG2: Single source record; no reconciliation required. | DH2: GitHub repository file listing (Alligator*_gs.jpg files), https://github.com/summoners29/Asphalt-Pavement-Crack-Data (accessed 2026-08-06) | DI2: Low | DJ2: Low | DK2: Use source record as cited. | DL2: 4 | DM2: 1 | DN2: 1 | DO2: 0 | DP2: 1 | DQ2: 1 | DR2: 0 | DS2: 27 | DT2: Reviewed (source MCDM_Scoring, averaged across batches) | DU2: 1 of 1 | DV2: =IFERROR(IF(INDEX(MCDM_Grades!$C$2:$C$178,MATCH($A2,MCDM_Grades!$A$2:$A$178,0))="","",INDEX(MCDM_Grades!$C$2:$C$178,MATCH($A2,MCDM_Grades!$A$2:$A$178,0))),"") | DW2: =IFERROR(IF(INDEX(MCDM_Grades!$D$2:$D$178,MATCH($A2,MCDM_Grades!$A$2:$A$178,0))="","",INDEX(MCDM_Grades!$D$2:$D$178,MATCH($A2,MCDM_Grades!$A$2:$A$178,0))),"") | DX2: =IFERROR(IF(INDEX(MCDM_Grades!$E$2:$E$178,MATCH($A2,MCDM_Grades!$A$2:$A$178,0))="","",INDEX(MCDM_Grades!$E$2:$E$178,MATCH($A2,MCDM_Grades!$A$2:$A$178,0))),"") | DY2: =IFERROR(IF(INDEX(MCDM_Grades!$F$2:$F$178,MATCH($A2,MCDM_Grades!$A$2:$A$178,0))="","",INDEX(MCDM_Grades!$F$2:$F$178,MATCH($A2,MCDM_Grades!$A$2:$A$178,0))),"") | DZ2: =IFERROR(IF(INDEX(MCDM_Grades!$G$2:$G$178,MATCH($A2,MCDM_Grades!$A$2:$A$178,0))="","",INDEX(MCDM_Grades!$G$2:$G$178,MATCH($A2,MCDM_Grades!$A$2:$A$178,0))),"") | EA2: =IFERROR(IF(INDEX(MCDM_Grades!$H$2:$H$178,MATCH($A2,MCDM_Grades!$A$2:$A$178,0))="","",INDEX(MCDM_Grades!$H$2:$H$178,MATCH($A2,MCDM_Grades!$A$2:$A$178,0))),"") | EB2: =IFERROR(IF(INDEX(MCDM_Grades!$I$2:$I$178,MATCH($A2,MCDM_Grades!$A$2:$A$178,0))="","",INDEX(MCDM_Grades!$I$2:$I$178,MATCH($A2,MCDM_Grades!$A$2:$A$178,0))),"") | EC2: =IFERROR(IF(INDEX(MCDM_Grades!$J$2:$J$178,MATCH($A2,MCDM_Grades!$A$2:$A$178,0))="","",INDEX(MCDM_Grades!$J$2:$J$178,MATCH($A2,MCDM_Grades!$A$2:$A$178,0))),"") | ED2: =IFERROR(IF(INDEX(MCDM_Grades!$N$2:$N$178,MATCH($A2,MCDM_Grades!$A$2:$A$178,0))="","",INDEX(MCDM_Grades!$N$2:$N$178,MATCH($A2,MCDM_Grades!$A$2:$A$178,0))),"") | EE2: =IFERROR(IF(INDEX(MCDM_Grades!$O$2:$O$178,MATCH($A2,MCDM_Grades!$A$2:$A$178,0))="","",INDEX(MCDM_Grades!$O$2:$O$178,MATCH($A2,MCDM_Grades!$A$2:$A$178,0))),"") | EF2: =IFERROR(IF(INDEX(MCDM_Grades!$P$2:$P$178,MATCH($A2,MCDM_Grades!$A$2:$A$178,0))="","",INDEX(MCDM_Grades!$P$2:$P$178,MATCH($A2,MCDM_Grades!$A$2:$A$178,0))),"") | EG2: =IFERROR(IF(INDEX(MCDM_Grades!$Q$2:$Q$178,MATCH($A2,MCDM_Grades!$A$2:$A$178,0))="","",INDEX(MCDM_Grades!$Q$2:$Q$178,MATCH($A2,MCDM_Grades!$A$2:$A$178,0))),"") | EH2: =IFERROR(IF(INDEX(MCDM_Grades!$R$2:$R$178,MATCH($A2,MCDM_Grades!$A$2:$A$178,0))="","",INDEX(MCDM_Grades!$R$2:$R$178,MATCH($A2,MCDM_Grades!$A$2:$A$178,0))),"") | EI2: =IFERROR(IF(INDEX(MCDM_Grades!$S$2:$S$178,MATCH($A2,MCDM_Grades!$A$2:$A$178,0))="","",INDEX(MCDM_Grades!$S$2:$S$178,MATCH($A2,MCDM_Grades!$A$2:$A$178,0))),"") | EJ2: =IFERROR(IF(INDEX(MCDM_Grades!$T$2:$T$178,MATCH($A2,MCDM_Grades!$A$2:$A$178,0))="","",INDEX(MCDM_Grades!$T$2:$T$178,MATCH($A2,MCDM_Grades!$A$2:$A$178,0))),"") | EK2: =IFERROR(IF(INDEX(MCDM_Grades!$U$2:$U$178,MATCH($A2,MCDM_Grades!$A$2:$A$178,0))="","",INDEX(MCDM_Grades!$U$2:$U$178,MATCH($A2,MCDM_Grades!$A$2:$A$178,0))),"") | EL2: =IFERROR(IF(INDEX(MCDM_Grades!$V$2:$V$178,MATCH($A2,MCDM_Grades!$A$2:$A$178,0))="","",INDEX(MCDM_Grades!$V$2:$V$178,MATCH($A2,MCDM_Grades!$A$2:$A$178,0))),"") | EM2: =IFERROR(IF(INDEX(MCDM_Grades!$W$2:$W$178,MATCH($A2,MCDM_Grades!$A$2:$A$178,0))="","",INDEX(MCDM_Grades!$W$2:$W$178,MATCH($A2,MCDM_Grades!$A$2:$A$178,0))),"") | EN2: =IFERROR(IF(INDEX(MCDM_Grades!$X$2:$X$178,MATCH($A2,MCDM_Grades!$A$2:$A$178,0))="","",INDEX(MCDM_Grades!$X$2:$X$178,MATCH($A2,MCDM_Grades!$A$2:$A$178,0))),"") | EO2: =IFERROR(IF(INDEX(MCDM_Grades!$Y$2:$Y$178,MATCH($A2,MCDM_Grades!$A$2:$A$178,0))="","",INDEX(MCDM_Grades!$Y$2:$Y$178,MATCH($A2,MCDM_Grades!$A$2:$A$178,0))),"") | EP2: =IFERROR(IF(INDEX(MCDM_Grades!$Z$2:$Z$178,MATCH($A2,MCDM_Grades!$A$2:$A$178,0))="","",INDEX(MCDM_Grades!$Z$2:$Z$178,MATCH($A2,MCDM_Grades!$A$2:$A$178,0))),"") | EQ2: =IFERROR(IF(INDEX(MCDM_Grades!$AA$2:$AA$178,MATCH($A2,MCDM_Grades!$A$2:$A$178,0))="","",INDEX(MCDM_Grades!$AA$2:$AA$178,MATCH($A2,MCDM_Grades!$A$2:$A$178,0))),"") | ER2: =IFERROR(IF(INDEX(MCDM_Grades!$AB$2:$AB$178,MATCH($A2,MCDM_Grades!$A$2:$A$178,0))="","",INDEX(MCDM_Grades!$AB$2:$AB$178,MATCH($A2,MCDM_Grades!$A$2:$A$178,0))),"") | ES2: =IFERROR(IF(INDEX(MCDM_Grades!$AC$2:$AC$178,MATCH($A2,MCDM_Grades!$A$2:$A$178,0))="","",INDEX(MCDM_Grades!$AC$2:$AC$178,MATCH($A2,MCDM_Grades!$A$2:$A$178,0))),"") | ET2: =IFERROR(IF(INDEX(MCDM_Grades!$AD$2:$AD$178,MATCH($A2,MCDM_Grades!$A$2:$A$178,0))="","",INDEX(MCDM_Grades!$AD$2:$AD$178,MATCH($A2,MCDM_Grades!$A$2:$A$178,0))),"") | EU2: =IFERROR(IF(INDEX(MCDM_Grades!$AE$2:$AE$178,MATCH($A2,MCDM_Grades!$A$2:$A$178,0))="","",INDEX(MCDM_Grades!$AE$2:$AE$178,MATCH($A2,MCDM_Grades!$A$2:$A$178,0))),"") | EV2: =IFERROR(IF(INDEX(MCDM_Grades!$K$2:$K$178,MATCH($A2,MCDM_Grades!$A$2:$A$178,0))="","",INDEX(MCDM_Grades!$K$2:$K$178,MATCH($A2,MCDM_Grades!$A$2:$A$178,0))),"") | EW2: =IFERROR(IF(INDEX(MCDM_Grades!$L$2:$L$178,MATCH($A2,MCDM_Grades!$A$2:$A$178,0))="","",INDEX(MCDM_Grades!$L$2:$L$178,MATCH($A2,MCDM_Grades!$A$2:$A$178,0))),"") | EX2: =IFERROR(IF(INDEX(MCDM_Grades!$M$2:$M$178,MATCH($A2,MCDM_Grades!$A$2:$A$178,0))="","",INDEX(MCDM_Grades!$M$2:$M$178,MATCH($A2,MCDM_Grades!$A$2:$A$178,0))),"") | EY2: =IFERROR(IF(INDEX(MCDM_Grades!$AR$2:$AR$178,MATCH($A2,MCDM_Grades!$A$2:$A$178,0))="","",INDEX(MCDM_Grades!$AR$2:$AR$178,MATCH($A2,MCDM_Grades!$A$2:$A$178,0))),"") | EZ2: =IFERROR(IF(INDEX(MCDM_Grades!$AS$2:$AS$178,MATCH($A2,MCDM_Grades!$A$2:$A$178,0))="","",INDEX(MCDM_Grades!$AS$2:$AS$178,MATCH($A2,MCDM_Grades!$A$2:$A$178,0))),"") | FA2: =IFERROR(IF(INDEX(MCDM_Grades!$AT$2:$AT$178,MATCH($A2,MCDM_Grades!$A$2:$A$178,0))="","",INDEX(MCDM_Grades!$AT$2:$AT$178,MATCH($A2,MCDM_Grades!$A$2:$A$178,0))),"") | FB2: =IFERROR(IF(INDEX(MCDM_Grades!$AU$2:$AU$178,MATCH($A2,MCDM_Grades!$A$2:$A$178,0))="","",INDEX(MCDM_Grades!$AU$2:$AU$178,MATCH($A2,MCDM_Grades!$A$2:$A$178,0))),"") | FC2: Nadir / top-down | FD2: Yes | FE2: No | FG2: Not reported (sample image consistent with a handheld camera pointed straight down at the surface) | FH2: Asphalt pavement crack image data | FI2: Dataset page / README | FJ2: https://github.com/summoners29/Asphalt-Pavement-Crack-Data/blob/master/Alligator001_gs.jpg | FK2: Medium | FL2: Verified - agreed | FM2: Workbook has all acquisition fields NR and the repo has no README (only the one-line description quoted; files Alligator001-028_gs.jpg, Pothole001-019_gs.jpg, Reflection001-058_gs.jpg on branch master). Label comes from viewing the sample image Alligator001_gs.jpg (2048x1536, grayscale): a full-frame close-up of the pavement surface with no horizon, road edge or perspective, i.e. camera optical axis perpendicular to the surface. Only one image was inspected and no capture device is documented, hence Medium. | Second review: Independently inspected a second sample from a different class (Pothole001_gs.jpg) in addition to the reviewer's Alligator001: it is likewise a surface-perpendicular close-up, supporting nadir. No README or device documentation exists, so Medium confidence is appropriate.
A3: DS-002 | B3: Asphalt Pavement Distress Dataset (DSWMamba) | C3: DSWMamba Asphalt Pavement Distress Dataset | D3: v1 | E3: Probable Match | F3: Moderate | G3: All three records describe the six-category asphalt distress dataset of the DSWMamba paper; GPT and Claude cite the Oct-Sunn/Asphalt-Pavement-Distress-Dataset repository, the Test batch cites zyf991121/DSWMamba (the model repository). | H3: Claude; GPT; GitHub_Test_Batch (tool UNK) | I3: GitHub | J3: N | K3: Two related GitHub repositories (dataset repo and model repo) for the same paper dataset | L3: https://github.com/Oct-Sunn/Asphalt-Pavement-Distress-Dataset | M3: https://github.com/Oct-Sunn/Asphalt-Pavement-Distress-Dataset; https://github.com/zyf991121/DSWMamba | N3: NA | O3: NA | P3: NA | Q3: NA | R3: NA | S3: NA | T3: NR | U3: Y | V3: DSWMamba paper (full bibliographic details not provided in README) [Claude] | DSWMamba paper cited by repository; DOI NR [GPT] | https://github.com/zyf991121/DSWMamba [Test_Batch] | W3: NR | X3: https://github.com/zyf991121/DSWMamba | Y3: NR | Z3: NR | AA3: Reported in source record (relationship not classified) | AB3: NR | AC3: NR | AD3: NR | AE3: NR | AF3: NR | AG3: NR | AH3: NR | AI3: NR | AJ3: NR | AK3: NR | AL3: NR | AM3: NR | AN3: NR | AO3: NR | AP3: NR | AQ3: NR | AR3: NR | AS3: Road environment: Asphalt pavements, real-world scenarios [Claude] | Asphalt pavement [GPT] | Asphalt roadway [Test_Batch] | AT3: NR | AU3: NR | AV3: NR | AW3: NR | AX3: NR | AY3: NR | AZ3: NR | BA3: NR | BB3: N | BC3: NR | BD3: NR | BE3: NR | BF3: NR | BG3: NR | BH3: Six distress categories incl. cracks, potholes, alligator cracks, road-marking distress [Claude] | six categories including cracks; potholes; alligator cracks; road-marking distress [GPT] | six asphalt pavement distress categories [Test_Batch] | BI3: NR | BJ3: Labeled images across six distress categories [Claude] | Six categories; full taxonomy NR [GPT] | six distress categories [Test_Batch] | BK3: NR | BL3: Detection/classification (per paper focus) [Claude] | detection; classification [GPT] | Semantic segmentation [Test_Batch] | BM3: Detection/classification (per paper focus) [Claude] | detection; classification [GPT] | Semantic segmentation [Test_Batch] | BN3: Pixel masks | BO3: mask | BP3: Y | BQ3: Y | BR3: Y | BS3: NR | BT3: NR | BU3: NR | BV3: N | BW3: N | BX3: N | BY3: Labeled images; details NR [GPT] | Manual annotation [Test_Batch] | BZ3: NR | CA3: NR | CB3: NR | CC3: Object detection [Claude] | detection; classification; analysis [GPT] | semantic segmentation [Test_Batch] | CD3: NR | CE3: NR | CF3: Reported on the source record/data card or associated publication (see Evidence_Locator) | CG3: NR | CH3: NR | CI3: Include-Supplementary [Claude] | Pending [GPT/Test_Batch] | CJ3: Direct_Download [Claude] | UNK [GPT/Test_Batch] | CK3: NR | CL3: N | CM3: Direct_Download [Claude] | UNK [GPT/Test_Batch] | CN3: NR | CO3: NR | CP3: N | CQ3: Image count, format, license, and provenance undocumented; single Google Drive archive (link liveness not independently re-tested) [Claude] | Download target not resolved; no count, license, persistent data identifier, annotation format, geography, or collection details [GPT] | Model repository documents a six-class dataset, but dataset count, release year, access route, license, geography, and independent dataset identity remain unresolved. [Test_Batch] | CR3: Original | CS3: N | CT3: N | CU3: N | CV3: NA | CW3: NA | CX3: ChatGPT_Github_001.xlsx; Claude_Github_001.xlsx; Github_Github_Test.xlsx | CY3: ChatGPT_Github_001:GH-016; Claude_Github_001:GH-DS-016; Github_Github_Test:GITHUB-034 | CZ3: Y - see conflict columns and Reconciliation_Notes | DA3: Y - see conflict columns and Reconciliation_Notes | DB3: None | DC3: Distress types: Six distress categories incl. cracks, potholes, alligator cracks, road-marking d (Claude) vs six categories including cracks; potholes; alligator cracks; road-marking distre (GPT) vs six asphalt pavement distress categories (Test_Batch) || Label taxonomy: Labeled images across six distress categories (Claude) vs Six categories; full taxonomy NR (GPT) vs six distress categories (Test_Batch) || Annotation task: Detection/classification (per paper focus) (Claude) vs detection; classification (GPT) vs Semantic segmentation (Test_Batch) || Annotation method: Labeled images; details NR (GPT) vs Manual annotation (Test_Batch) | DD3: None | DE3: Access status: Direct_Download (Claude) vs UNK (GPT/Test_Batch) || AI tasks: Object detection (Claude) vs detection; classification; analysis (GPT) vs semantic segmentation (Test_Batch) || Screening decision: Include-Supplementary (Claude) vs Pending (GPT/Test_Batch) || Road environment: Asphalt pavements, real-world scenarios (Claude) vs Asphalt pavement (GPT) vs Asphalt roadway (Test_Batch) || Publications: DSWMamba paper (full bibliographic details not provided in README) (Claude) vs DSWMamba paper cited by repository; DOI NR (GPT) vs https://github.com/zyf991121/DSWMamba (Test_Batch) || Key_Limitations: Image count, format, license, and provenance undocumented; single Google Drive a (Claude) vs Download target not resolved; no count, license, persistent data identifier, ann (GPT) vs Model repository documents a six-class dataset, but dataset count, release year, (Test_Batch) | DF3: Y | DG3: No definitive identifier (no DOI, counts NR); URL conflict between the two repositories; screening conflict Pending (GPT, Test) vs Include-Supplementary (Claude). | DH3: GitHub README (Details, download link), https://github.com/Oct-Sunn/Asphalt-Pavement-Distress-Dataset (accessed 2026-08-06) [Claude] | https://github.com/Oct-Sunn/Asphalt-Pavement-Distress-Dataset README; accessed 2026-08-06 [GPT] | https://github.com/zyf991121/DSWMamba; README dataset description checked 2026-08-01 [Test_Batch] | DI3: Low | DJ3: High | DK3: Confirm dataset release location and extent. | DL3: 2 | DM3: 2 | DN3: 1.7 | DO3: 0.3 | DP3: 1.7 | DQ3: 0.7 | DR3: 0 | DS3: 26.8 | DT3: Reviewed (source MCDM_Scoring, averaged across batches) | DU3: 3 of 3 | DV3: =IFERROR(IF(INDEX(MCDM_Grades!$C$2:$C$178,MATCH($A3,MCDM_Grades!$A$2:$A$178,0))="","",INDEX(MCDM_Grades!$C$2:$C$178,MATCH($A3,MCDM_Grades!$A$2:$A$178,0))),"") | DW3: =IFERROR(IF(INDEX(MCDM_Grades!$D$2:$D$178,MATCH($A3,MCDM_Grades!$A$2:$A$178,0))="","",INDEX(MCDM_Grades!$D$2:$D$178,MATCH($A3,MCDM_Grades!$A$2:$A$178,0))),"") | DX3: =IFERROR(IF(INDEX(MCDM_Grades!$E$2:$E$178,MATCH($A3,MCDM_Grades!$A$2:$A$178,0))="","",INDEX(MCDM_Grades!$E$2:$E$178,MATCH($A3,MCDM_Grades!$A$2:$A$178,0))),"") | DY3: =IFERROR(IF(INDEX(MCDM_Grades!$F$2:$F$178,MATCH($A3,MCDM_Grades!$A$2:$A$178,0))="","",INDEX(MCDM_Grades!$F$2:$F$178,MATCH($A3,MCDM_Grades!$A$2:$A$178,0))),"") | DZ3: =IFERROR(IF(INDEX(MCDM_Grades!$G$2:$G$178,MATCH($A3,MCDM_Grades!$A$2:$A$178,0))="","",INDEX(MCDM_Grades!$G$2:$G$178,MATCH($A3,MCDM_Grades!$A$2:$A$178,0))),"") | EA3: =IFERROR(IF(INDEX(MCDM_Grades!$H$2:$H$178,MATCH($A3,MCDM_Grades!$A$2:$A$178,0))="","",INDEX(MCDM_Grades!$H$2:$H$178,MATCH($A3,MCDM_Grades!$A$2:$A$178,0))),"") | EB3: =IFERROR(IF(INDEX(MCDM_Grades!$I$2:$I$178,MATCH($A3,MCDM_Grades!$A$2:$A$178,0))="","",INDEX(MCDM_Grades!$I$2:$I$178,MATCH($A3,MCDM_Grades!$A$2:$A$178,0))),"") | EC3: =IFERROR(IF(INDEX(MCDM_Grades!$J$2:$J$178,MATCH($A3,MCDM_Grades!$A$2:$A$178,0))="","",INDEX(MCDM_Grades!$J$2:$J$178,MATCH($A3,MCDM_Grades!$A$2:$A$178,0))),"") | ED3: =IFERROR(IF(INDEX(MCDM_Grades!$N$2:$N$178,MATCH($A3,MCDM_Grades!$A$2:$A$178,0))="","",INDEX(MCDM_Grades!$N$2:$N$178,MATCH($A3,MCDM_Grades!$A$2:$A$178,0))),"") | EE3: =IFERROR(IF(INDEX(MCDM_Grades!$O$2:$O$178,MATCH($A3,MCDM_Grades!$A$2:$A$178,0))="","",INDEX(MCDM_Grades!$O$2:$O$178,MATCH($A3,MCDM_Grades!$A$2:$A$178,0))),"") | EF3: =IFERROR(IF(INDEX(MCDM_Grades!$P$2:$P$178,MATCH($A3,MCDM_Grades!$A$2:$A$178,0))="","",INDEX(MCDM_Grades!$P$2:$P$178,MATCH($A3,MCDM_Grades!$A$2:$A$178,0))),"") | EG3: =IFERROR(IF(INDEX(MCDM_Grades!$Q$2:$Q$178,MATCH($A3,MCDM_Grades!$A$2:$A$178,0))="","",INDEX(MCDM_Grades!$Q$2:$Q$178,MATCH($A3,MCDM_Grades!$A$2:$A$178,0))),"") | EH3: =IFERROR(IF(INDEX(MCDM_Grades!$R$2:$R$178,MATCH($A3,MCDM_Grades!$A$2:$A$178,0))="","",INDEX(MCDM_Grades!$R$2:$R$178,MATCH($A3,MCDM_Grades!$A$2:$A$178,0))),"") | EI3: =IFERROR(IF(INDEX(MCDM_Grades!$S$2:$S$178,MATCH($A3,MCDM_Grades!$A$2:$A$178,0))="","",INDEX(MCDM_Grades!$S$2:$S$178,MATCH($A3,MCDM_Grades!$A$2:$A$178,0))),"") | EJ3: =IFERROR(IF(INDEX(MCDM_Grades!$T$2:$T$178,MATCH($A3,MCDM_Grades!$A$2:$A$178,0))="","",INDEX(MCDM_Grades!$T$2:$T$178,MATCH($A3,MCDM_Grades!$A$2:$A$178,0))),"") | EK3: =IFERROR(IF(INDEX(MCDM_Grades!$U$2:$U$178,MATCH($A3,MCDM_Grades!$A$2:$A$178,0))="","",INDEX(MCDM_Grades!$U$2:$U$178,MATCH($A3,MCDM_Grades!$A$2:$A$178,0))),"") | EL3: =IFERROR(IF(INDEX(MCDM_Grades!$V$2:$V$178,MATCH($A3,MCDM_Grades!$A$2:$A$178,0))="","",INDEX(MCDM_Grades!$V$2:$V$178,MATCH($A3,MCDM_Grades!$A$2:$A$178,0))),"") | EM3: =IFERROR(IF(INDEX(MCDM_Grades!$W$2:$W$178,MATCH($A3,MCDM_Grades!$A$2:$A$178,0))="","",INDEX(MCDM_Grades!$W$2:$W$178,MATCH($A3,MCDM_Grades!$A$2:$A$178,0))),"") | EN3: =IFERROR(IF(INDEX(MCDM_Grades!$X$2:$X$178,MATCH($A3,MCDM_Grades!$A$2:$A$178,0))="","",INDEX(MCDM_Grades!$X$2:$X$178,MATCH($A3,MCDM_Grades!$A$2:$A$178,0))),"") | EO3: =IFERROR(IF(INDEX(MCDM_Grades!$Y$2:$Y$178,MATCH($A3,MCDM_Grades!$A$2:$A$178,0))="","",INDEX(MCDM_Grades!$Y$2:$Y$178,MATCH($A3,MCDM_Grades!$A$2:$A$178,0))),"") | EP3: =IFERROR(IF(INDEX(MCDM_Grades!$Z$2:$Z$178,MATCH($A3,MCDM_Grades!$A$2:$A$178,0))="","",INDEX(MCDM_Grades!$Z$2:$Z$178,MATCH($A3,MCDM_Grades!$A$2:$A$178,0))),"") | EQ3: =IFERROR(IF(INDEX(MCDM_Grades!$AA$2:$AA$178,MATCH($A3,MCDM_Grades!$A$2:$A$178,0))="","",INDEX(MCDM_Grades!$AA$2:$AA$178,MATCH($A3,MCDM_Grades!$A$2:$A$178,0))),"") | ER3: =IFERROR(IF(INDEX(MCDM_Grades!$AB$2:$AB$178,MATCH($A3,MCDM_Grades!$A$2:$A$178,0))="","",INDEX(MCDM_Grades!$AB$2:$AB$178,MATCH($A3,MCDM_Grades!$A$2:$A$178,0))),"") | ES3: =IFERROR(IF(INDEX(MCDM_Grades!$AC$2:$AC$178,MATCH($A3,MCDM_Grades!$A$2:$A$178,0))="","",INDEX(MCDM_Grades!$AC$2:$AC$178,MATCH($A3,MCDM_Grades!$A$2:$A$178,0))),"") | ET3: =IFERROR(IF(INDEX(MCDM_Grades!$AD$2:$AD$178,MATCH($A3,MCDM_Grades!$A$2:$A$178,0))="","",INDEX(MCDM_Grades!$AD$2:$AD$178,MATCH($A3,MCDM_Grades!$A$2:$A$178,0))),"") | EU3: =IFERROR(IF(INDEX(MCDM_Grades!$AE$2:$AE$178,MATCH($A3,MCDM_Grades!$A$2:$A$178,0))="","",INDEX(MCDM_Grades!$AE$2:$AE$178,MATCH($A3,MCDM_Grades!$A$2:$A$178,0))),"") | EV3: =IFERROR(IF(INDEX(MCDM_Grades!$K$2:$K$178,MATCH($A3,MCDM_Grades!$A$2:$A$178,0))="","",INDEX(MCDM_Grades!$K$2:$K$178,MATCH($A3,MCDM_Grades!$A$2:$A$178,0))),"") | EW3: =IFERROR(IF(INDEX(MCDM_Grades!$L$2:$L$178,MATCH($A3,MCDM_Grades!$A$2:$A$178,0))="","",INDEX(MCDM_Grades!$L$2:$L$178,MATCH($A3,MCDM_Grades!$A$2:$A$178,0))),"") | EX3: =IFERROR(IF(INDEX(MCDM_Grades!$M$2:$M$178,MATCH($A3,MCDM_Grades!$A$2:$A$178,0))="","",INDEX(MCDM_Grades!$M$2:$M$178,MATCH($A3,MCDM_Grades!$A$2:$A$178,0))),"") | EY3: =IFERROR(IF(INDEX(MCDM_Grades!$AR$2:$AR$178,MATCH($A3,MCDM_Grades!$A$2:$A$178,0))="","",INDEX(MCDM_Grades!$AR$2:$AR$178,MATCH($A3,MCDM_Grades!$A$2:$A$178,0))),"") | EZ3: =IFERROR(IF(INDEX(MCDM_Grades!$AS$2:$AS$178,MATCH($A3,MCDM_Grades!$A$2:$A$178,0))="","",INDEX(MCDM_Grades!$AS$2:$AS$178,MATCH($A3,MCDM_Grades!$A$2:$A$178,0))),"") | FA3: =IFERROR(IF(INDEX(MCDM_Grades!$AT$2:$AT$178,MATCH($A3,MCDM_Grades!$A$2:$A$178,0))="","",INDEX(MCDM_Grades!$AT$2:$AT$178,MATCH($A3,MCDM_Grades!$A$2:$A$178,0))),"") | FB3: =IFERROR(IF(INDEX(MCDM_Grades!$AU$2:$AU$178,MATCH($A3,MCDM_Grades!$A$2:$A$178,0))="","",INDEX(MCDM_Grades!$AU$2:$AU$178,MATCH($A3,MCDM_Grades!$A$2:$A$178,0))),"") | FC3: Not reported | FD3: Unknown | FE3: Unknown | FG3: Not reported | FH3: Download target not resolved; no count, license, persistent data identifier, annotation format, geography, or collection details | FI3: None | FK3: Medium | FL3: Not independently verified | FM3: All workbook acquisition fields NR. Fetched https://github.com/Oct-Sunn/Asphalt-Pavement-Distress-Dataset: README only says the dataset 'features labeled images of asphalt conditions across six distress categories' and links a Google Drive archive; no camera, platform or viewpoint statement. The model repository https://github.com/zyf991121/DSWMamba returned HTTP 404. A web search found the DSWMamba paper (Construction and Building Materials, S0950061825005410; 13,129 images, six distress types) but only the paywalled abstract, which does not describe acquisition. Medium rather than High because the full paper (not fetched within the 2-fetch budget) may document the camera set-up.
A4: DS-003 | B4: CiCS pavement crack image dataset | C4: NA | D4: v1 (in-repo rar archives, 5 parts) | E4: Independent Dataset | F4: NA (single source record) | G4: Single source record; no matching record found in any other file after cross-file and cross-platform comparison. | H4: Claude | I4: GitHub | J4: N | K4: NA (single platform) | L4: https://github.com/DrEdwardLee/Pavement-Crack-Dataset | M4: https://github.com/DrEdwardLee/Pavement-Crack-Dataset | N4: NA | O4: NA | P4: NA | Q4: NA | R4: NA | S4: NA | T4: NR | U4: N | V4: NR | W4: NR | X4: NR | Y4: NR | Z4: NA | AA4: NA | AB4: NR | AC4: NR | AD4: NR | AE4: NR | AF4: NR | AG4: NR | AH4: NR | AI4: NR | AJ4: NR | AK4: NR | AL4: NR | AM4: NR | AN4: NR | AO4: NR | AP4: NR | AQ4: NR | AR4: NR | AS4: Road environment: Pavements | AT4: NR | AU4: NR | AV4: NR | AW4: NR | AX4: NR | AY4: NR | AZ4: NR | BA4: NR | BB4: NR | BC4: NR | BD4: NR | BE4: NR | BF4: NR | BG4: NR | BH4: Pavement cracks (undifferentiated crack class) | BI4: NR | BJ4: UNK (no README; annotation presence not verifiable from file listing) | BK4: NR | BL4: NR | BM4: NR | BN4: NR | BO4: NR | BP4: NR | BQ4: NR | BR4: NR | BS4: NR | BT4: NR | BU4: NR | BV4: NR | BW4: NR | BX4: NR | BY4: NR | BZ4: NR | CA4: NR | CB4: NR | CC4: Crack detection (per repo description) | CD4: NR | CE4: NR | CF4: Reported on the source record/data card or associated publication (see Evidence_Locator) | CG4: NR | CH4: NR | CI4: Include-Supplementary | CJ4: Direct_Download | CK4: NR | CL4: N | CM4: Direct_Download | CN4: NR | CO4: NR | CP4: N | CQ4: No README or documentation; annotations, counts, provenance, and license all unverified (data stored as CiCS-Data(1-5).rar in repo) | CR4: Original | CS4: N | CT4: N | CU4: N | CV4: NA | CW4: CrackBlock600k (same CiCS acquisition-system lineage); LEiS pavement crack image dataset (same repository) | CX4: Claude_Github_001.xlsx | CY4: Claude_Github_001:GH-DS-019 | CZ4: N | DA4: NA | DB4: None | DC4: None | DD4: None | DE4: None | DF4: N | DG4: Single source record; no reconciliation required. | DH4: GitHub repository file listing, https://github.com/DrEdwardLee/Pavement-Crack-Dataset (accessed 2026-08-06) | DI4: Low | DJ4: Low | DK4: Use source record as cited. | DL4: 4 | DM4: 1 | DN4: 1 | DO4: 0 | DP4: 1 | DQ4: 1 | DR4: 0 | DS4: 27 | DT4: Reviewed (source MCDM_Scoring, averaged across batches) | DU4: 1 of 1 | DV4: =IFERROR(IF(INDEX(MCDM_Grades!$C$2:$C$178,MATCH($A4,MCDM_Grades!$A$2:$A$178,0))="","",INDEX(MCDM_Grades!$C$2:$C$178,MATCH($A4,MCDM_Grades!$A$2:$A$178,0))),"") | DW4: =IFERROR(IF(INDEX(MCDM_Grades!$D$2:$D$178,MATCH($A4,MCDM_Grades!$A$2:$A$178,0))="","",INDEX(MCDM_Grades!$D$2:$D$178,MATCH($A4,MCDM_Grades!$A$2:$A$178,0))),"") | DX4: =IFERROR(IF(INDEX(MCDM_Grades!$E$2:$E$178,MATCH($A4,MCDM_Grades!$A$2:$A$178,0))="","",INDEX(MCDM_Grades!$E$2:$E$178,MATCH($A4,MCDM_Grades!$A$2:$A$178,0))),"") | DY4: =IFERROR(IF(INDEX(MCDM_Grades!$F$2:$F$178,MATCH($A4,MCDM_Grades!$A$2:$A$178,0))="","",INDEX(MCDM_Grades!$F$2:$F$178,MATCH($A4,MCDM_Grades!$A$2:$A$178,0))),"") | DZ4: =IFERROR(IF(INDEX(MCDM_Grades!$G$2:$G$178,MATCH($A4,MCDM_Grades!$A$2:$A$178,0))="","",INDEX(MCDM_Grades!$G$2:$G$178,MATCH($A4,MCDM_Grades!$A$2:$A$178,0))),"") | EA4: =IFERROR(IF(INDEX(MCDM_Grades!$H$2:$H$178,MATCH($A4,MCDM_Grades!$A$2:$A$178,0))="","",INDEX(MCDM_Grades!$H$2:$H$178,MATCH($A4,MCDM_Grades!$A$2:$A$178,0))),"") | EB4: =IFERROR(IF(INDEX(MCDM_Grades!$I$2:$I$178,MATCH($A4,MCDM_Grades!$A$2:$A$178,0))="","",INDEX(MCDM_Grades!$I$2:$I$178,MATCH($A4,MCDM_Grades!$A$2:$A$178,0))),"") | EC4: =IFERROR(IF(INDEX(MCDM_Grades!$J$2:$J$178,MATCH($A4,MCDM_Grades!$A$2:$A$178,0))="","",INDEX(MCDM_Grades!$J$2:$J$178,MATCH($A4,MCDM_Grades!$A$2:$A$178,0))),"") | ED4: =IFERROR(IF(INDEX(MCDM_Grades!$N$2:$N$178,MATCH($A4,MCDM_Grades!$A$2:$A$178,0))="","",INDEX(MCDM_Grades!$N$2:$N$178,MATCH($A4,MCDM_Grades!$A$2:$A$178,0))),"") | EE4: =IFERROR(IF(INDEX(MCDM_Grades!$O$2:$O$178,MATCH($A4,MCDM_Grades!$A$2:$A$178,0))="","",INDEX(MCDM_Grades!$O$2:$O$178,MATCH($A4,MCDM_Grades!$A$2:$A$178,0))),"") | EF4: =IFERROR(IF(INDEX(MCDM_Grades!$P$2:$P$178,MATCH($A4,MCDM_Grades!$A$2:$A$178,0))="","",INDEX(MCDM_Grades!$P$2:$P$178,MATCH($A4,MCDM_Grades!$A$2:$A$178,0))),"") | EG4: =IFERROR(IF(INDEX(MCDM_Grades!$Q$2:$Q$178,MATCH($A4,MCDM_Grades!$A$2:$A$178,0))="","",INDEX(MCDM_Grades!$Q$2:$Q$178,MATCH($A4,MCDM_Grades!$A$2:$A$178,0))),"") | EH4: =IFERROR(IF(INDEX(MCDM_Grades!$R$2:$R$178,MATCH($A4,MCDM_Grades!$A$2:$A$178,0))="","",INDEX(MCDM_Grades!$R$2:$R$178,MATCH($A4,MCDM_Grades!$A$2:$A$178,0))),"") | EI4: =IFERROR(IF(INDEX(MCDM_Grades!$S$2:$S$178,MATCH($A4,MCDM_Grades!$A$2:$A$178,0))="","",INDEX(MCDM_Grades!$S$2:$S$178,MATCH($A4,MCDM_Grades!$A$2:$A$178,0))),"") | EJ4: =IFERROR(IF(INDEX(MCDM_Grades!$T$2:$T$178,MATCH($A4,MCDM_Grades!$A$2:$A$178,0))="","",INDEX(MCDM_Grades!$T$2:$T$178,MATCH($A4,MCDM_Grades!$A$2:$A$178,0))),"") | EK4: =IFERROR(IF(INDEX(MCDM_Grades!$U$2:$U$178,MATCH($A4,MCDM_Grades!$A$2:$A$178,0))="","",INDEX(MCDM_Grades!$U$2:$U$178,MATCH($A4,MCDM_Grades!$A$2:$A$178,0))),"") | EL4: =IFERROR(IF(INDEX(MCDM_Grades!$V$2:$V$178,MATCH($A4,MCDM_Grades!$A$2:$A$178,0))="","",INDEX(MCDM_Grades!$V$2:$V$178,MATCH($A4,MCDM_Grades!$A$2:$A$178,0))),"") | EM4: =IFERROR(IF(INDEX(MCDM_Grades!$W$2:$W$178,MATCH($A4,MCDM_Grades!$A$2:$A$178,0))="","",INDEX(MCDM_Grades!$W$2:$W$178,MATCH($A4,MCDM_Grades!$A$2:$A$178,0))),"") | EN4: =IFERROR(IF(INDEX(MCDM_Grades!$X$2:$X$178,MATCH($A4,MCDM_Grades!$A$2:$A$178,0))="","",INDEX(MCDM_Grades!$X$2:$X$178,MATCH($A4,MCDM_Grades!$A$2:$A$178,0))),"") | EO4: =IFERROR(IF(INDEX(MCDM_Grades!$Y$2:$Y$178,MATCH($A4,MCDM_Grades!$A$2:$A$178,0))="","",INDEX(MCDM_Grades!$Y$2:$Y$178,MATCH($A4,MCDM_Grades!$A$2:$A$178,0))),"") | EP4: =IFERROR(IF(INDEX(MCDM_Grades!$Z$2:$Z$178,MATCH($A4,MCDM_Grades!$A$2:$A$178,0))="","",INDEX(MCDM_Grades!$Z$2:$Z$178,MATCH($A4,MCDM_Grades!$A$2:$A$178,0))),"") | EQ4: =IFERROR(IF(INDEX(MCDM_Grades!$AA$2:$AA$178,MATCH($A4,MCDM_Grades!$A$2:$A$178,0))="","",INDEX(MCDM_Grades!$AA$2:$AA$178,MATCH($A4,MCDM_Grades!$A$2:$A$178,0))),"") | ER4: =IFERROR(IF(INDEX(MCDM_Grades!$AB$2:$AB$178,MATCH($A4,MCDM_Grades!$A$2:$A$178,0))="","",INDEX(MCDM_Grades!$AB$2:$AB$178,MATCH($A4,MCDM_Grades!$A$2:$A$178,0))),"") | ES4: =IFERROR(IF(INDEX(MCDM_Grades!$AC$2:$AC$178,MATCH($A4,MCDM_Grades!$A$2:$A$178,0))="","",INDEX(MCDM_Grades!$AC$2:$AC$178,MATCH($A4,MCDM_Grades!$A$2:$A$178,0))),"") | ET4: =IFERROR(IF(INDEX(MCDM_Grades!$AD$2:$AD$178,MATCH($A4,MCDM_Grades!$A$2:$A$178,0))="","",INDEX(MCDM_Grades!$AD$2:$AD$178,MATCH($A4,MCDM_Grades!$A$2:$A$178,0))),"") | EU4: =IFERROR(IF(INDEX(MCDM_Grades!$AE$2:$AE$178,MATCH($A4,MCDM_Grades!$A$2:$A$178,0))="","",INDEX(MCDM_Grades!$AE$2:$AE$178,MATCH($A4,MCDM_Grades!$A$2:$A$178,0))),"") | EV4: =IFERROR(IF(INDEX(MCDM_Grades!$K$2:$K$178,MATCH($A4,MCDM_Grades!$A$2:$A$178,0))="","",INDEX(MCDM_Grades!$K$2:$K$178,MATCH($A4,MCDM_Grades!$A$2:$A$178,0))),"") | EW4: =IFERROR(IF(INDEX(MCDM_Grades!$L$2:$L$178,MATCH($A4,MCDM_Grades!$A$2:$A$178,0))="","",INDEX(MCDM_Grades!$L$2:$L$178,MATCH($A4,MCDM_Grades!$A$2:$A$178,0))),"") | EX4: =IFERROR(IF(INDEX(MCDM_Grades!$M$2:$M$178,MATCH($A4,MCDM_Grades!$A$2:$A$178,0))="","",INDEX(MCDM_Grades!$M$2:$M$178,MATCH($A4,MCDM_Grades!$A$2:$A$178,0))),"") | EY4: =IFERROR(IF(INDEX(MCDM_Grades!$AR$2:$AR$178,MATCH($A4,MCDM_Grades!$A$2:$A$178,0))="","",INDEX(MCDM_Grades!$AR$2:$AR$178,MATCH($A4,MCDM_Grades!$A$2:$A$178,0))),"") | EZ4: =IFERROR(IF(INDEX(MCDM_Grades!$AS$2:$AS$178,MATCH($A4,MCDM_Grades!$A$2:$A$178,0))="","",INDEX(MCDM_Grades!$AS$2:$AS$178,MATCH($A4,MCDM_Grades!$A$2:$A$178,0))),"") | FA4: =IFERROR(IF(INDEX(MCDM_Grades!$AT$2:$AT$178,MATCH($A4,MCDM_Grades!$A$2:$A$178,0))="","",INDEX(MCDM_Grades!$AT$2:$AT$178,MATCH($A4,MCDM_Grades!$A$2:$A$178,0))),"") | FB4: =IFERROR(IF(INDEX(MCDM_Grades!$AU$2:$AU$178,MATCH($A4,MCDM_Grades!$A$2:$A$178,0))="","",INDEX(MCDM_Grades!$AU$2:$AU$178,MATCH($A4,MCDM_Grades!$A$2:$A$178,0))),"") | FC4: Not reported | FD4: Unknown | FE4: Unknown | FG4: Not reported | FH4: No README or documentation; annotations, counts, provenance, and license all unverified (data stored as CiCS-Data(1-5).rar in repo) | FI4: None | FK4: Medium | FL4: Not independently verified | FM4: Workbook acquisition fields all NR and no publication. Fetched https://github.com/DrEdwardLee/Pavement-Crack-Dataset: only the tagline 'We have published two new pavement crack image dataset, named Cics Dataset and Leis Dataset' and rar archives (CiCS-Data parts 1-5, LEiS-Data, CrackForest-Data, MPS-Dataset); the acronyms CiCS/LEiS are not expanded and no camera or viewpoint is described. A web search for 'CiCS' 'LEiS' pavement crack returned nothing relevant. The workbook's Related_Datasets note ('same CiCS acquisition-system lineage' with CrackBlock600k) hints at a dedicated acquisition system, but its geometry is undocumented in any reachable source, so Medium.
