Workbook

Sheet Top10_Review
A2: Ten datasets for manual review
A3: Review order covers contrasting data types and verification issues. It is a purposive shortlist, not a ranking by documentation score.
A5: Priority | B5: Dataset ID | C5: Dataset | D5: Representation | E5: Lower /100 | F5: Upper /100 | G5: Resolved share | H5: Dataset link | I5: Paper / evidence | J5: Why selected | K5: First manual action | L5: Release / scope | M5: Known limitation | N5: Review status | O5: Review inputs | P5: Check evidence
A6: 1 | B6: DS-084 | C6: SDNET2018 — pavement subset | D6: Binary image classification | E6: =INDEX(MCDM_Grades!$E$6:$E$238,MATCH(B6,MCDM_Grades!$A$6:$A$238,0)) -> 88.888889 | F6: =INDEX(MCDM_Grades!$F$6:$F$238,MATCH(B6,MCDM_Grades!$A$6:$A$238,0)) -> 100 | G6: =INDEX(MCDM_Grades!$G$6:$G$238,MATCH(B6,MCDM_Grades!$A$6:$A$238,0)) -> 0.88888889 | H6: =HYPERLINK("https://digitalcommons.usu.edu/all_datasets/48/","Dataset") -> Dataset | I6: =HYPERLINK("https://doi.org/10.1016/j.dib.2018.11.015","Evidence") -> Evidence | J6: Compact class-folder example; checks whether pavement crops are distinguished from walls/decks and original captures. | K6: Open USU Methodology and ReadMe; identify pavement C/U folders; then inspect one cracked and one uncracked crop. | L6: USU SDNET2018 deposit, 2018; pavement subset within full release | M6: Whole-deposit count is not pavement-only count; related crops are not independent images. No payload inspection. | N6: =INDEX(Manual_Review!$AH$6:$AH$238,MATCH(B6,Manual_Review!$A$6:$A$238,0)) -> Not started | O6: =HYPERLINK("#'Manual_Review'!A"&(MATCH("DS-084",Manual_Review!$A$6:$A$238,0)+5),"Enter review") -> Enter review | P6: =HYPERLINK("#'MCDM_Checks'!A"&(MATCH("DS-084",MCDM_Checks!$B$6:$B$3733,0)+5),"Check evidence") -> Check evidence
A7: 2 | B7: DS-007 | C7: CRACK500 | D7: Crack segmentation | E7: =INDEX(MCDM_Grades!$E$6:$E$238,MATCH(B7,MCDM_Grades!$A$6:$A$238,0)) -> 77.777778 | F7: =INDEX(MCDM_Grades!$F$6:$F$238,MATCH(B7,MCDM_Grades!$A$6:$A$238,0)) -> 100 | G7: =INDEX(MCDM_Grades!$G$6:$G$238,MATCH(B7,MCDM_Grades!$A$6:$A$238,0)) -> 0.77777778 | H7: =HYPERLINK("https://github.com/fyangneil/pavement-crack-detection","Dataset") -> Dataset | I7: =HYPERLINK("https://arxiv.org/abs/1901.06340","Evidence") -> Evidence | J7: Small original corpus with clear original-image/crop distinction; useful calibration for sampling and ancestry. | K7: Read paper IV-B1; verify 500 original images versus 3,368 retained crops and map one image to its binary mask. | L7: FPHBN documented CRACK500 split, 2019 paper / author repository | M7: Repository bundles other datasets. Do not count companion corpora as CRACK500. Data terms and label QA remain unresolved. | N7: =INDEX(Manual_Review!$AH$6:$AH$238,MATCH(B7,Manual_Review!$A$6:$A$238,0)) -> Not started | O7: =HYPERLINK("#'Manual_Review'!A"&(MATCH("DS-007",Manual_Review!$A$6:$A$238,0)+5),"Enter review") -> Enter review | P7: =HYPERLINK("#'MCDM_Checks'!A"&(MATCH("DS-007",MCDM_Checks!$B$6:$B$3733,0)+5),"Check evidence") -> Check evidence
A8: 3 | B8: DS-035 | C8: RDD2022 | D8: Multicountry distress detection | E8: =INDEX(MCDM_Grades!$E$6:$E$238,MATCH(B8,MCDM_Grades!$A$6:$A$238,0)) -> 94.444444 | F8: =INDEX(MCDM_Grades!$F$6:$F$238,MATCH(B8,MCDM_Grades!$A$6:$A$238,0)) -> 100 | G8: =INDEX(MCDM_Grades!$G$6:$G$238,MATCH(B8,MCDM_Grades!$A$6:$A$238,0)) -> 0.94444444 | H8: =HYPERLINK("https://figshare.com/articles/dataset/RDD2022_-_The_multi-national_Road_Damage_Dataset_released_through_CRDDC_2022/21431547/1","Dataset") -> Dataset | I8: =HYPERLINK("https://arxiv.org/abs/2209.08538","Evidence") -> Evidence | J8: Well-documented detection exemplar with country subsets, label map and download manifest. | K8: Open label_map.pbtxt and directory structure; inspect one public training XML; note test annotations are withheld. | L8: Figshare version 1, DOI 10.6084/m9.figshare.21431547.v1 | M8: Contains earlier RDD lineage. Country folders do not prove route-independent splits; third-party rights require separate reuse check. | N8: =INDEX(Manual_Review!$AH$6:$AH$238,MATCH(B8,Manual_Review!$A$6:$A$238,0)) -> Not started | O8: =HYPERLINK("#'Manual_Review'!A"&(MATCH("DS-035",Manual_Review!$A$6:$A$238,0)+5),"Enter review") -> Enter review | P8: =HYPERLINK("#'MCDM_Checks'!A"&(MATCH("DS-035",MCDM_Checks!$B$6:$B$3733,0)+5),"Check evidence") -> Check evidence
A9: 4 | B9: DS-096 | C9: PaveBench / PaveVQA | D9: Multitask perception and vision-language | E9: =INDEX(MCDM_Grades!$E$6:$E$238,MATCH(B9,MCDM_Grades!$A$6:$A$238,0)) -> 100 | F9: =INDEX(MCDM_Grades!$F$6:$F$238,MATCH(B9,MCDM_Grades!$A$6:$A$238,0)) -> 100 | G9: =INDEX(MCDM_Grades!$G$6:$G$238,MATCH(B9,MCDM_Grades!$A$6:$A$238,0)) -> 1 | H9: =HYPERLINK("https://huggingface.co/datasets/MML-Group/PaveBench","Dataset") -> Dataset | I9: =HYPERLINK("https://arxiv.org/abs/2604.02804","Evidence") -> Evidence | J9: Meeting-critical example; public task tree makes differences among classification, detection, masks and VQA easy to check. | K9: Compare six classification categories with merged detection/segmentation classes; inspect label_map.txt and one QA record. | L9: Hugging Face MML-Group/PaveBench, current card snapshot 2026-10-11 | M9: Documentation-only pass does not validate mask accuracy, physical metrology, benchmark independence or maintenance outcomes. | N9: =INDEX(Manual_Review!$AH$6:$AH$238,MATCH(B9,Manual_Review!$A$6:$A$238,0)) -> Not started | O9: =HYPERLINK("#'Manual_Review'!A"&(MATCH("DS-096",Manual_Review!$A$6:$A$238,0)+5),"Enter review") -> Enter review | P9: =HYPERLINK("#'MCDM_Checks'!A"&(MATCH("DS-096",MCDM_Checks!$B$6:$B$3733,0)+5),"Check evidence") -> Check evidence
A10: 5 | B10: DS-011 | C10: CrackSeg9k | D10: Compiled derivative and lineage audit | E10: =INDEX(MCDM_Grades!$E$6:$E$238,MATCH(B10,MCDM_Grades!$A$6:$A$238,0)) -> 58.333333 | F10: =INDEX(MCDM_Grades!$F$6:$F$238,MATCH(B10,MCDM_Grades!$A$6:$A$238,0)) -> 100 | G10: =INDEX(MCDM_Grades!$G$6:$G$238,MATCH(B10,MCDM_Grades!$A$6:$A$238,0)) -> 0.58333333 | H10: =HYPERLINK("https://dataverse.harvard.edu/dataset.xhtml?persistentId=doi:10.7910/DVN/EGIEBY&version=4.0","Dataset") -> Dataset | I10: =HYPERLINK("https://arxiv.org/abs/2208.13054","Evidence") -> Evidence | J10: Deliberate derivative exemplar exposes parent overlap, annotation transformations and changed release counts. | K10: Open author README V4 instructions; reconcile approximately 9,160 current images with 9,255 in the paper; inspect parent prefixes. | L10: Author-recommended Dataverse V4, June 2024; release content requires reconciliation | M10: Shares parents with SDNET2018 and CRACK500 in this shortlist. Not an independent external test. V4 payload not inspected. | N10: =INDEX(Manual_Review!$AH$6:$AH$238,MATCH(B10,Manual_Review!$A$6:$A$238,0)) -> Not started | O10: =HYPERLINK("#'Manual_Review'!A"&(MATCH("DS-011",Manual_Review!$A$6:$A$238,0)+5),"Enter review") -> Enter review | P10: =HYPERLINK("#'MCDM_Checks'!A"&(MATCH("DS-011",MCDM_Checks!$B$6:$B$3733,0)+5),"Check evidence") -> Check evidence
A11: 6 | B11: DS-135 | C11: UAV-PDD2023 | D11: UAV distress detection | E11: =INDEX(MCDM_Grades!$E$6:$E$238,MATCH(B11,MCDM_Grades!$A$6:$A$238,0)) -> 100 | F11: =INDEX(MCDM_Grades!$F$6:$F$238,MATCH(B11,MCDM_Grades!$A$6:$A$238,0)) -> 100 | G11: =INDEX(MCDM_Grades!$G$6:$G$238,MATCH(B11,MCDM_Grades!$A$6:$A$238,0)) -> 1 | H11: =HYPERLINK("https://zenodo.org/records/8429208","Dataset") -> Dataset | I11: =HYPERLINK("https://doi.org/10.1016/j.dib.2023.109692","Evidence") -> Evidence | J11: Stable DOI and compact data paper provide an accessible UAV example with concrete label-overlay verification. | K11: Open paper Figures 2–3 and XML example; verify six class codes, 2,440 images and one image-label overlay. | L11: Zenodo v4, 2023-10-11; DOI 10.5281/zenodo.8429208 | M11: Images include crops and augmentation. Random splits do not establish original-frame independence; route groups remain unverified. | N11: =INDEX(Manual_Review!$AH$6:$AH$238,MATCH(B11,Manual_Review!$A$6:$A$238,0)) -> Not started | O11: =HYPERLINK("#'Manual_Review'!A"&(MATCH("DS-135",Manual_Review!$A$6:$A$238,0)+5),"Enter review") -> Enter review | P11: =HYPERLINK("#'MCDM_Checks'!A"&(MATCH("DS-135",MCDM_Checks!$B$6:$B$3733,0)+5),"Check evidence") -> Check evidence
A12: 7 | B12: DS-157 | C12: Pothole-600 | D12: RGB and transformed-disparity segmentation | E12: =INDEX(MCDM_Grades!$E$6:$E$238,MATCH(B12,MCDM_Grades!$A$6:$A$238,0)) -> 55.555556 | F12: =INDEX(MCDM_Grades!$F$6:$F$238,MATCH(B12,MCDM_Grades!$A$6:$A$238,0)) -> 100 | G12: =INDEX(MCDM_Grades!$G$6:$G$238,MATCH(B12,MCDM_Grades!$A$6:$A$238,0)) -> 0.55555556 | H12: =HYPERLINK("https://sites.google.com/view/pothole-600/dataset","Dataset") -> Dataset | I12: =HYPERLINK("https://arxiv.org/abs/2008.06840","Evidence") -> Evidence | J12: Manageable multimodal exemplar with 600 paired items and a clear source site; useful contrast between imagery and metrology. | K12: Follow official Dataset page to Drive/Kaggle; match one RGB image, transformed disparity and mask; confirm data terms. | L12: Author Pothole-600 release accompanying ECCV Workshops 2020 | M12: Distinguish from separate 2019 Stereo Pothole Datasets. Transformation is not calibrated pothole depth; license/QA/location remain unresolved. | N12: =INDEX(Manual_Review!$AH$6:$AH$238,MATCH(B12,Manual_Review!$A$6:$A$238,0)) -> Not started | O12: =HYPERLINK("#'Manual_Review'!A"&(MATCH("DS-157",Manual_Review!$A$6:$A$238,0)+5),"Enter review") -> Enter review | P12: =HYPERLINK("#'MCDM_Checks'!A"&(MATCH("DS-157",MCDM_Checks!$B$6:$B$3733,0)+5),"Check evidence") -> Check evidence
A13: 8 | B13: DS-160 | C13: PVS — Passive Vehicular Sensors | D13: Inertial sensors and roughness categories | E13: =INDEX(MCDM_Grades!$E$6:$E$238,MATCH(B13,MCDM_Grades!$A$6:$A$238,0)) -> 75 | F13: =INDEX(MCDM_Grades!$F$6:$F$238,MATCH(B13,MCDM_Grades!$A$6:$A$238,0)) -> 100 | G13: =INDEX(MCDM_Grades!$G$6:$G$238,MATCH(B13,MCDM_Grades!$A$6:$A$238,0)) -> 0.75 | H13: =HYPERLINK("https://github.com/jefmenegazzo/Intelligent-Vehicle-Perception-Based-on-Inertial-Sensing-and-Artificial-Intelligence","Dataset") -> Dataset | I13: =HYPERLINK("https://doi.org/10.1109/SBESC51047.2020.9277846","Evidence") -> Evidence | J13: Nine-run example makes non-image units, sensor rates and category-versus-measured-IRI distinction practical to review. | K13: Read sensor and run tables; check one dataset_labels.csv with its GPS record and environmental-video timestamp. | L13: Nine-run PVS family; author README snapshot 2026-10-11 | M13: Three vehicle/driver pairs are confounded. Roughness classes are not measured IRI. Missing codes, label QA and terms scope need confirmation. | N13: =INDEX(Manual_Review!$AH$6:$AH$238,MATCH(B13,Manual_Review!$A$6:$A$238,0)) -> Not started | O13: =HYPERLINK("#'Manual_Review'!A"&(MATCH("DS-160",Manual_Review!$A$6:$A$238,0)+5),"Enter review") -> Enter review | P13: =HYPERLINK("#'MCDM_Checks'!A"&(MATCH("DS-160",MCDM_Checks!$B$6:$B$3733,0)+5),"Check evidence") -> Check evidence
A14: 9 | B14: DS-047 | C14: LTPP — Long-Term Pavement Performance | D14: Engineering measurements and longitudinal sections | E14: =INDEX(MCDM_Grades!$E$6:$E$238,MATCH(B14,MCDM_Grades!$A$6:$A$238,0)) -> 83.333333 | F14: =INDEX(MCDM_Grades!$F$6:$F$238,MATCH(B14,MCDM_Grades!$A$6:$A$238,0)) -> 100 | G14: =INDEX(MCDM_Grades!$G$6:$G$238,MATCH(B14,MCDM_Grades!$A$6:$A$238,0)) -> 0.83333333 | H14: =HYPERLINK("https://infopave.fhwa.dot.gov/Data/StandardDataRelease","Dataset") -> Dataset | I14: =HYPERLINK("https://infopave.fhwa.dot.gov/InfoPave_Repository/files/FHWA-HRT-21-038.pdf","Evidence") -> Evidence | J14: Essential engineering contrast; manual pilot can focus on one section and measurement table rather than the entire database. | K14: Confirm SDR selection, open LTPPDD and MON_DIS_AC_REV definitions, then inspect one section/date with null-versus-zero handling. | L14: SDR39 context retained from v4; current portal identifies SDR40 as latest; selection pending | M14: Release-specific counts/distributions and schema continuity remain pending; 2021 guide is context, not proof of SDR39/40 completeness. | N14: =INDEX(Manual_Review!$AH$6:$AH$238,MATCH(B14,Manual_Review!$A$6:$A$238,0)) -> Not started | O14: =HYPERLINK("#'Manual_Review'!A"&(MATCH("DS-047",Manual_Review!$A$6:$A$238,0)+5),"Enter review") -> Enter review | P14: =HYPERLINK("#'MCDM_Checks'!A"&(MATCH("DS-047",MCDM_Checks!$B$6:$B$3733,0)+5),"Check evidence") -> Check evidence
A15: 10 | B15: DS-183 | C15: Zenseact Open Dataset — Frames | D15: AV fleet road wetness and snow classification | E15: =INDEX(MCDM_Grades!$E$6:$E$238,MATCH(B15,MCDM_Grades!$A$6:$A$238,0)) -> 88.888889 | F15: =INDEX(MCDM_Grades!$F$6:$F$238,MATCH(B15,MCDM_Grades!$A$6:$A$238,0)) -> 100 | G15: =INDEX(MCDM_Grades!$G$6:$G$238,MATCH(B15,MCDM_Grades!$A$6:$A$238,0)) -> 0.88888889 | H15: =HYPERLINK("https://zod.zenseact.com/frames/","Dataset") -> Dataset | I15: =HYPERLINK("https://arxiv.org/abs/2305.02008","Evidence") -> Evidence | J15: New AV-inventory exemplar with public samples, concise surface-label definitions and an SDK mini-download option. | K15: Open Annotations → Road surface and Frames samples; verify wetness/snow labels in one Frame; check access route before retrieval. | L15: ZOD Frames public documentation snapshot 2026-10-11; distinguish Sequences/Drives | M15: Surface labels apply to Frames; do not infer labels on every video frame or autonomous engagement. Not crack/PCI ground truth. | N15: =INDEX(Manual_Review!$AH$6:$AH$238,MATCH(B15,Manual_Review!$A$6:$A$238,0)) -> Not started | O15: =HYPERLINK("#'Manual_Review'!A"&(MATCH("DS-183",Manual_Review!$A$6:$A$238,0)+5),"Enter review") -> Enter review | P15: =HYPERLINK("#'MCDM_Checks'!A"&(MATCH("DS-183",MCDM_Checks!$B$6:$B$3733,0)+5),"Check evidence") -> Check evidence

Sheet All_Datasets
A2: Merged dataset inventory
A3: 233 retained records from 248 source rows. Blue rows are the ten purposive manual-review priorities. Scores are provisional documentation bounds.
A5: Dataset ID | B5: Dataset / release | C5: Review priority | D5: Profile | E5: Lower /100 | F5: Upper /100 | G5: Resolved share | H5: Dataset link | I5: Evidence / paper | J5: Assessed release | K5: Task / target scope | L5: Media | M5: Capture context | N5: Labels / targets | O5: Annotation format | P5: Stated terms | Q5: Access route | R5: Reported size and unit | S5: Geography | T5: Publisher | U5: Limitations | V5: Source IDs | W5: Merge decision | X5: Related-release flags | Y5: Conflicts / release issues | Z5: Evidence basis | AA5: Manual review | AB5: Check evidence | AC5: Platforms | AD5: Primary URL | AE5: Evidence URL | AF5: Source lineage
A6: DS-001 | B6: Asphalt Pavement Crack Data (class-foldered grayscale images) | D6: Labeled-16 | E6: =INDEX(MCDM_Grades!$E$6:$E$238,MATCH(A6,MCDM_Grades!$A$6:$A$238,0)) -> 11.111111 | F6: =INDEX(MCDM_Grades!$F$6:$F$238,MATCH(A6,MCDM_Grades!$A$6:$A$238,0)) -> 100 | G6: =INDEX(MCDM_Grades!$G$6:$G$238,MATCH(A6,MCDM_Grades!$A$6:$A$238,0)) -> 0.11111111 | H6: =HYPERLINK("https://github.com/summoners29/Asphalt-Pavement-Crack-Data","Dataset") -> Dataset | I6: =HYPERLINK("https://github.com/summoners29/Asphalt-Pavement-Crack-Data","Evidence / paper") -> Evidence / paper | J6: v1 | K6: Classification | L6: NR | M6: NR | N6: Folder-level class labels (e.g., Alligator) | O6: Class-folder structure (grayscale jpg) | P6: NR | Q6: Direct_Download | R6: NR | S6: Road environment: Asphalt pavements | U6: No README, no counts, no license or provenance; images stored directly in repository | V6: DS-001 | W6: Retained existing record | Z6: v3 evidence snapshot | AA6: =HYPERLINK("#'Manual_Review'!A"&(MATCH("DS-001",Manual_Review!$A$6:$A$238,0)+5),"Enter review") -> Enter review | AB6: =HYPERLINK("#'MCDM_Checks'!A"&(MATCH("DS-001",MCDM_Checks!$B$6:$B$3733,0)+5),"Check evidence") -> Check evidence | AC6: GitHub | AD6: https://github.com/summoners29/Asphalt-Pavement-Crack-Data | AE6: https://github.com/summoners29/Asphalt-Pavement-Crack-Data | AF6: Compared_All_Platforms_TH_v3.0.xlsx!All_Datasets row 2 (DS-001)
A7: DS-002 | B7: Asphalt Pavement Distress Dataset (DSWMamba) | D7: Labeled-16 | E7: =INDEX(MCDM_Grades!$E$6:$E$238,MATCH(A7,MCDM_Grades!$A$6:$A$238,0)) -> 11.111111 | F7: =INDEX(MCDM_Grades!$F$6:$F$238,MATCH(A7,MCDM_Grades!$A$6:$A$238,0)) -> 100 | G7: =INDEX(MCDM_Grades!$G$6:$G$238,MATCH(A7,MCDM_Grades!$A$6:$A$238,0)) -> 0.11111111 | H7: =HYPERLINK("https://github.com/Oct-Sunn/Asphalt-Pavement-Distress-Dataset","Dataset") -> Dataset | I7: =HYPERLINK("https://github.com/Oct-Sunn/Asphalt-Pavement-Distress-Dataset","Evidence / paper") -> Evidence / paper | J7: v1 | K7: Object detection [Claude] | detection; classification; analysis [GPT] | semantic segmentation [Test_Batch] | L7: NR | M7: NR | N7: Labeled images across six distress categories [Claude] | Six categories; full taxonomy NR [GPT] | six distress categories [Test_Batch] | O7: Pixel masks | P7: NR | Q7: Direct_Download [Claude] | UNK [GPT/Test_Batch] | R7: NR | S7: Road environment: Asphalt pavements, real-world scenarios [Claude] | Asphalt pavement [GPT] | Asphalt roadway [Test_Batch] | U7: Image count, format, license, and provenance undocumented; single Google Drive archive (link liveness not independently re-tested) [Claude] | Download target not resolved; no count, license, persistent data identifier, annotation format, geography, or collection details [GPT] | Model repository documents a six-class dataset, but dataset count, release year, access route, license, geography, and independent dataset identity remain unresolved. [Test_Batch] | V7: DS-002 | W7: Retained existing record | Z7: v3 evidence snapshot | AA7: =HYPERLINK("#'Manual_Review'!A"&(MATCH("DS-002",Manual_Review!$A$6:$A$238,0)+5),"Enter review") -> Enter review | AB7: =HYPERLINK("#'MCDM_Checks'!A"&(MATCH("DS-002",MCDM_Checks!$B$6:$B$3733,0)+5),"Check evidence") -> Check evidence | AC7: GitHub | AD7: https://github.com/Oct-Sunn/Asphalt-Pavement-Distress-Dataset | AE7: https://github.com/Oct-Sunn/Asphalt-Pavement-Distress-Dataset | AF7: Compared_All_Platforms_TH_v3.0.xlsx!All_Datasets row 3 (DS-002)
A8: DS-003 | B8: CiCS pavement crack image dataset | D8: Labeled-16 | E8: =INDEX(MCDM_Grades!$E$6:$E$238,MATCH(A8,MCDM_Grades!$A$6:$A$238,0)) -> 11.111111 | F8: =INDEX(MCDM_Grades!$F$6:$F$238,MATCH(A8,MCDM_Grades!$A$6:$A$238,0)) -> 100 | G8: =INDEX(MCDM_Grades!$G$6:$G$238,MATCH(A8,MCDM_Grades!$A$6:$A$238,0)) -> 0.11111111 | H8: =HYPERLINK("https://github.com/DrEdwardLee/Pavement-Crack-Dataset","Dataset") -> Dataset | I8: =HYPERLINK("https://github.com/DrEdwardLee/Pavement-Crack-Dataset","Evidence / paper") -> Evidence / paper | J8: v1 (in-repo rar archives, 5 parts) | K8: Crack detection (per repo description) | L8: NR | M8: NR | N8: UNK (no README; annotation presence not verifiable from file listing) | O8: NR | P8: NR | Q8: Direct_Download | R8: NR | S8: Road environment: Pavements | U8: No README or documentation; annotations, counts, provenance, and license all unverified (data stored as CiCS-Data(1-5).rar in repo) | V8: DS-003 | W8: Retained existing record | X8: Same acquisition lineage; different archives/releases (DS-003, DS-025, DS-090) | Z8: v3 evidence snapshot | AA8: =HYPERLINK("#'Manual_Review'!A"&(MATCH("DS-003",Manual_Review!$A$6:$A$238,0)+5),"Enter review") -> Enter review | AB8: =HYPERLINK("#'MCDM_Checks'!A"&(MATCH("DS-003",MCDM_Checks!$B$6:$B$3733,0)+5),"Check evidence") -> Check evidence | AC8: GitHub | AD8: https://github.com/DrEdwardLee/Pavement-Crack-Dataset | AE8: https://github.com/DrEdwardLee/Pavement-Crack-Dataset | AF8: Compared_All_Platforms_TH_v3.0.xlsx!All_Datasets row 4 (DS-003)
A9: DS-004 | B9: complexPavementCrackDataset | D9: Labeled-16 | E9: =INDEX(MCDM_Grades!$E$6:$E$238,MATCH(A9,MCDM_Grades!$A$6:$A$238,0)) -> 36.111111 | F9: =INDEX(MCDM_Grades!$F$6:$F$238,MATCH(A9,MCDM_Grades!$A$6:$A$238,0)) -> 100 | G9: =INDEX(MCDM_Grades!$G$6:$G$238,MATCH(A9,MCDM_Grades!$A$6:$A$238,0)) -> 0.36111111 | H9: =HYPERLINK("https://github.com/SEU-zhc/complexPavementCrackDataset","Dataset") -> Dataset | I9: =HYPERLINK("https://github.com/SEU-zhc/complexPavementCrackDataset","Evidence / paper") -> Evidence / paper | J9: v1 | K9: Object detection;Semantic segmentation | L9: Images/frames as reported | M9: Onboard (vehicle) cameras | N9: Bounding boxes (class xc yc w h) and binary crack masks | O9: YOLO-style txt;binary mask images | P9: NR | Q9: Restricted | R9: 500 | S9: Road environment: Pavements with shadows, watermarks, brake marks and environmental noise | U9: Baidu-only hosting limits international research access; 'over 500 images' recorded as 500 minimum; no paper or license | V9: DS-004 | W9: Retained existing record | Z9: v3 evidence snapshot | AA9: =HYPERLINK("#'Manual_Review'!A"&(MATCH("DS-004",Manual_Review!$A$6:$A$238,0)+5),"Enter review") -> Enter review | AB9: =HYPERLINK("#'MCDM_Checks'!A"&(MATCH("DS-004",MCDM_Checks!$B$6:$B$3733,0)+5),"Check evidence") -> Check evidence | AC9: GitHub | AD9: https://github.com/SEU-zhc/complexPavementCrackDataset | AE9: https://github.com/SEU-zhc/complexPavementCrackDataset | AF9: Compared_All_Platforms_TH_v3.0.xlsx!All_Datasets row 5 (DS-004)
A10: DS-005 | B10: CQU-BPDD — Chongqing University Bituminous Pavement Disease Detection Dataset | D10: Labeled-16 | E10: =INDEX(MCDM_Grades!$E$6:$E$238,MATCH(A10,MCDM_Grades!$A$6:$A$238,0)) -> 61.111111 | F10: =INDEX(MCDM_Grades!$F$6:$F$238,MATCH(A10,MCDM_Grades!$A$6:$A$238,0)) -> 100 | G10: =INDEX(MCDM_Grades!$G$6:$G$238,MATCH(A10,MCDM_Grades!$A$6:$A$238,0)) -> 0.61111111 | H10: =HYPERLINK("https://huggingface.co/datasets/Dearcat/CQU-BPDD","Dataset") -> Dataset | I10: =HYPERLINK("https://github.com/DearCaat/Pavement-Distress-Classification","Evidence / paper") -> Evidence / paper | J10: 2020–2021; CQU-BPDD — Bituminous Pavement Distress | K10: Distress / roughness | L10: Images / patches | M10: Human-driven survey | N10: Transverse, longitudinal, massive and alligator crack; crack pouring; raveling; repair; normal. | O10: Image/patch classification | P10: CC BY-NC 4.0 (current author HF release) | Q10: Public links | R10: 60,056 images in current dataset card; paper abstract says 60,059 | S10: Southern China highways | T10: Chongqing University / Wenhao Tang, Sheng Huang and collaborators | U10: Count discrepancy retained. Strong distress classification data but specialized top-down survey imagery, not conventional AV forward footage. | V10: DS-005; D023 | W10: Same dataset, authorized host | Y10: Legacy license alternatives are superseded for the chosen HF release by current CC BY-NC 4.0 card; original repository also limits use to noncommercial. | Z10: AV inventory evidence snapshot | AA10: =HYPERLINK("#'Manual_Review'!A"&(MATCH("DS-005",Manual_Review!$A$6:$A$238,0)+5),"Enter review") -> Enter review | AB10: =HYPERLINK("#'MCDM_Checks'!A"&(MATCH("DS-005",MCDM_Checks!$B$6:$B$3733,0)+5),"Check evidence") -> Check evidence | AC10: Hugging Face; GitHub | AD10: https://huggingface.co/datasets/Dearcat/CQU-BPDD | AE10: https://github.com/DearCaat/Pavement-Distress-Classification | AF10: Compared_All_Platforms_TH_v3.0.xlsx!All_Datasets row 6 (DS-005); AV_Pavement_Dataset_Inventory.xlsx!Datasets row 29 (D023)
A11: DS-006 | B11: Crack Classification Dataset (five crack types, 200 images) | D11: Labeled-16 | E11: =INDEX(MCDM_Grades!$E$6:$E$238,MATCH(A11,MCDM_Grades!$A$6:$A$238,0)) -> 50 | F11: =INDEX(MCDM_Grades!$F$6:$F$238,MATCH(A11,MCDM_Grades!$A$6:$A$238,0)) -> 100 | G11: =INDEX(MCDM_Grades!$G$6:$G$238,MATCH(A11,MCDM_Grades!$A$6:$A$238,0)) -> 0.5 | H11: =HYPERLINK("https://github.com/0110TJY/Crack-Classification-Dataset","Dataset") -> Dataset | I11: =HYPERLINK("https://github.com/0110TJY/Crack-Classification-Dataset","Evidence / paper") -> Evidence / paper | J11: v1 | K11: Classification | L11: Images/frames as reported | M11: Partly author-captured; partly compiled from CRACK500 and CrackForest | N11: Class-level labels (five types) | O11: Class-folder / zip structure | P11: NR | Q11: Direct_Download | R11: 200 | S11: Road environment: Pavements | U11: Partially derivative of CRACK500/CFD; very small; class names undocumented | V11: DS-006 | W11: Retained existing record | Z11: v3 evidence snapshot | AA11: =HYPERLINK("#'Manual_Review'!A"&(MATCH("DS-006",Manual_Review!$A$6:$A$238,0)+5),"Enter review") -> Enter review | AB11: =HYPERLINK("#'MCDM_Checks'!A"&(MATCH("DS-006",MCDM_Checks!$B$6:$B$3733,0)+5),"Check evidence") -> Check evidence | AC11: GitHub | AD11: https://github.com/0110TJY/Crack-Classification-Dataset | AE11: https://github.com/0110TJY/Crack-Classification-Dataset | AF11: Compared_All_Platforms_TH_v3.0.xlsx!All_Datasets row 7 (DS-006)
A12: DS-007 | B12: CRACK500 (Crack500) | C12: 2 | D12: Labeled-16 | E12: =INDEX(MCDM_Grades!$E$6:$E$238,MATCH(A12,MCDM_Grades!$A$6:$A$238,0)) -> 77.777778 | F12: =INDEX(MCDM_Grades!$F$6:$F$238,MATCH(A12,MCDM_Grades!$A$6:$A$238,0)) -> 100 | G12: =INDEX(MCDM_Grades!$G$6:$G$238,MATCH(A12,MCDM_Grades!$A$6:$A$238,0)) -> 0.77777778 | H12: =HYPERLINK("https://github.com/fyangneil/pavement-crack-detection","Dataset") -> Dataset | I12: =HYPERLINK("https://arxiv.org/abs/1901.06340","Evidence / paper") -> Evidence / paper | J12: FPHBN documented CRACK500 split, 2019 paper / author repository | K12: Semantic segmentation;Crack detection [Claude/GPT/Test_Batch] | crack segmentation; crack detection [GPT] | L12: Images/frames as reported | M12: Hand-held smartphone (cell phone) [Claude] | Cellphone cameras [GPT] | Handheld smartphone [GPT] | Smartphone camera [Test_Batch] | N12: Binary crack vs background [Claude] | Pixel-level pavement-crack masks [GPT] | crack pixels; background pixels [GPT] | crack pixel mask [Test_Batch] | O12: Binary mask images [Claude] | Images and pixel-level ground-truth masks; cropped derivatives also commonly distributed [GPT] | pixel masks [GPT/Test_Batch] | P12: NR | Q12: Direct_Download [Claude/GPT/Test_Batch] | Registration [GPT] | R12: 500 [Claude/GPT/Test_Batch] | 3368 [GPT] | S12: United States; Temple University main campus, Philadelphia, PA [Claude] | Temple University campus;Philadelphia;Pennsylvania [GPT] | Temple University campus, Philadelphia [GPT] | Temple University campus, Philadelphia, Pennsylvania [Test_Batch]; Road environment: Campus pavements [Claude] | Campus pavement surfaces [GPT] | Campus roads; asphalt; cement; gravel [GPT] | Campus roads [Test_Batch] | U12: No explicit license; single-location smartphone capture limits diversity; data hosted on Google Drive/OneDrive/Baidu (link liveness not independently re-tested) [Claude] | Kaggle is a mirror; original dataset predates the Kaggle upload, licensing is unclear on the mirror, and cropped-patch counts should not be confused with the 500 original images. [GPT] | Crack-only; campus-scale geography; sparse engineering metadata; download links are maintained through code repositories [GPT] | Small original set from one campus; later cropped-image totals should not be confused with unique source-image count. [Test_Batch] | V12: DS-007 | W12: Retained existing record | X12: Shared host; distinct data (DS-007, DS-018); Parent and noisy-mask derivative (DS-007, DS-062); Compiled crack ancestry (DS-007, DS-008, DS-011, DS-016, DS-142) | Y12: Repository bundles other datasets. Do not count companion corpora as CRACK500. Data terms and label QA remain unresolved. | Z12: Primary documentation checked | AA12: =HYPERLINK("#'Manual_Review'!A"&(MATCH("DS-007",Manual_Review!$A$6:$A$238,0)+5),"Enter review") -> Enter review | AB12: =HYPERLINK("#'MCDM_Checks'!A"&(MATCH("DS-007",MCDM_Checks!$B$6:$B$3733,0)+5),"Check evidence") -> Check evidence | AC12: GitHub; Kaggle | AD12: https://github.com/fyangneil/pavement-crack-detection | AE12: https://arxiv.org/abs/1901.06340 | AF12: Compared_All_Platforms_TH_v3.0.xlsx!All_Datasets row 8 (DS-007)
A13: DS-008 | B13: CrackForest Dataset (CFD) | D13: Labeled-16 | E13: =INDEX(MCDM_Grades!$E$6:$E$238,MATCH(A13,MCDM_Grades!$A$6:$A$238,0)) -> 69.444444 | F13: =INDEX(MCDM_Grades!$F$6:$F$238,MATCH(A13,MCDM_Grades!$A$6:$A$238,0)) -> 100 | G13: =INDEX(MCDM_Grades!$G$6:$G$238,MATCH(A13,MCDM_Grades!$A$6:$A$238,0)) -> 0.69444444 | H13: =HYPERLINK("https://github.com/cuilimeng/CrackForest-dataset","Dataset") -> Dataset | I13: =HYPERLINK("https://github.com/cuilimeng/CrackForest-dataset","Evidence / paper") -> Evidence / paper | J13: NR | K13: semantic segmentation; crack detection | L13: Images/frames as reported | M13: iPhone 5 smartphone camera | N13: crack contour; crack pixel mask | O13: Ground-truth contour images | P13: NR | Q13: Direct_Download | R13: 118 | S13: China; Beijing; Road environment: Urban | U13: Very small single-city benchmark and limited collection-condition metadata. | V13: DS-008 | W13: Retained existing record | X13: Compiled crack ancestry (DS-007, DS-008, DS-011, DS-016, DS-142) | Z13: v3 evidence snapshot | AA13: =HYPERLINK("#'Manual_Review'!A"&(MATCH("DS-008",Manual_Review!$A$6:$A$238,0)+5),"Enter review") -> Enter review | AB13: =HYPERLINK("#'MCDM_Checks'!A"&(MATCH("DS-008",MCDM_Checks!$B$6:$B$3733,0)+5),"Check evidence") -> Check evidence | AC13: GitHub | AD13: https://github.com/cuilimeng/CrackForest-dataset | AE13: https://github.com/cuilimeng/CrackForest-dataset | AF13: Compared_All_Platforms_TH_v3.0.xlsx!All_Datasets row 9 (DS-008)
A14: DS-009 | B14: CrackLS315 | D14: Labeled-16 | E14: =INDEX(MCDM_Grades!$E$6:$E$238,MATCH(A14,MCDM_Grades!$A$6:$A$238,0)) -> 41.666667 | F14: =INDEX(MCDM_Grades!$F$6:$F$238,MATCH(A14,MCDM_Grades!$A$6:$A$238,0)) -> 100 | G14: =INDEX(MCDM_Grades!$G$6:$G$238,MATCH(A14,MCDM_Grades!$A$6:$A$238,0)) -> 0.41666667 | H14: =HYPERLINK("https://github.com/qinnzou/DeepCrack","Dataset") -> Dataset | I14: =HYPERLINK("https://github.com/qinnzou/DeepCrack","Evidence / paper") -> Evidence / paper | J14: CrackLS315 | K14: semantic segmentation; crack detection | L14: Images/frames as reported | M14: Laser-illuminated line-array camera | N14: crack pixel mask | O14: Image-mask pairs | P14: NR | Q14: Direct_Download | R14: 315 | S14: Road environment: Road pavement | U14: Small crack-only dataset; 1 mm ground sampling distance is reported, but pixel resolution, navigation, location, license, and weather metadata are not reported. | V14: DS-009 | W14: Retained existing record | X14: Shared host; distinct data (DS-009, DS-013, DS-014) | Z14: v3 evidence snapshot | AA14: =HYPERLINK("#'Manual_Review'!A"&(MATCH("DS-009",Manual_Review!$A$6:$A$238,0)+5),"Enter review") -> Enter review | AB14: =HYPERLINK("#'MCDM_Checks'!A"&(MATCH("DS-009",MCDM_Checks!$B$6:$B$3733,0)+5),"Check evidence") -> Check evidence | AC14: GitHub | AD14: https://github.com/qinnzou/DeepCrack | AE14: https://github.com/qinnzou/DeepCrack | AF14: Compared_All_Platforms_TH_v3.0.xlsx!All_Datasets row 10 (DS-009)
A15: DS-010 | B15: Cracks and Potholes in Road Images Dataset (DNIT, Brazil) | D15: Labeled-16 | E15: =INDEX(MCDM_Grades!$E$6:$E$238,MATCH(A15,MCDM_Grades!$A$6:$A$238,0)) -> 58.333333 | F15: =INDEX(MCDM_Grades!$F$6:$F$238,MATCH(A15,MCDM_Grades!$A$6:$A$238,0)) -> 100 | G15: =INDEX(MCDM_Grades!$G$6:$G$238,MATCH(A15,MCDM_Grades!$A$6:$A$238,0)) -> 0.58333333 | H15: =HYPERLINK("https://data.mendeley.com/datasets/t576ydh9v8/4","Dataset") -> Dataset | I15: =HYPERLINK("https://data.mendeley.com/datasets/t576ydh9v8/4","Evidence / paper") -> Evidence / paper | J15: 4 | K15: Semantic segmentation;Defect detection [GPT] | classification; object detection [Test_Batch] | L15: Images/frames as reported | M15: DNIT road-survey imagery; platform NR | N15: Road;crack;pothole masks [GPT] | road; crack; pothole [Test_Batch] | O15: PNG binary masks | P15: CC BY 4.0 | Q15: Direct_Download | R15: 2235 | S15: Brazil; Espírito Santo;Rio Grande do Sul;Federal District; Road environment: Highways [GPT] | Roadway [Test_Batch] | U15: Images collected partly before project years, but qualifying dataset release is 2020; limited sensor and condition metadata [GPT] | Release year, formal license, exact annotation format, and authoritative count documentation remain unresolved. [Test_Batch] | V15: DS-010 | W15: Retained existing record | Z15: v3 evidence snapshot | AA15: =HYPERLINK("#'Manual_Review'!A"&(MATCH("DS-010",Manual_Review!$A$6:$A$238,0)+5),"Enter review") -> Enter review | AB15: =HYPERLINK("#'MCDM_Checks'!A"&(MATCH("DS-010",MCDM_Checks!$B$6:$B$3733,0)+5),"Check evidence") -> Check evidence | AC15: Mendeley Data; GitHub | AD15: https://data.mendeley.com/datasets/t576ydh9v8/4 | AE15: https://data.mendeley.com/datasets/t576ydh9v8/4 | AF15: Compared_All_Platforms_TH_v3.0.xlsx!All_Datasets row 11 (DS-010)
A16: DS-011 | B16: CrackSeg9k | C16: 5 | D16: Labeled-16 | E16: =INDEX(MCDM_Grades!$E$6:$E$238,MATCH(A16,MCDM_Grades!$A$6:$A$238,0)) -> 58.333333 | F16: =INDEX(MCDM_Grades!$F$6:$F$238,MATCH(A16,MCDM_Grades!$A$6:$A$238,0)) -> 100 | G16: =INDEX(MCDM_Grades!$G$6:$G$238,MATCH(A16,MCDM_Grades!$A$6:$A$238,0)) -> 0.58333333 | H16: =HYPERLINK("https://dataverse.harvard.edu/dataset.xhtml?persistentId=doi:10.7910/DVN/EGIEBY&version=4.0","Dataset") -> Dataset | I16: =HYPERLINK("https://arxiv.org/abs/2208.13054","Evidence / paper") -> Evidence / paper | J16: Author-recommended Dataverse V4, June 2024; release content requires reconciliation | K16: semantic segmentation | L16: NR | M16: Multiple source datasets | N16: crack pixel mask | O16: Image-mask pairs | P16: NR | Q16: Direct_Download | R16: NR | S16: Road environment: Roadway; mixed structures and materials | U16: Approximately 9,160 images are reported, but the corpus combines road and non-road crack sources and may duplicate underlying datasets. | V16: DS-011 | W16: Retained existing record | X16: Compiled crack ancestry (DS-007, DS-008, DS-011, DS-016, DS-142) | Y16: Shares parents with SDNET2018 and CRACK500 in this shortlist. Not an independent external test. V4 payload not inspected. | Z16: Primary documentation checked | AA16: =HYPERLINK("#'Manual_Review'!A"&(MATCH("DS-011",Manual_Review!$A$6:$A$238,0)+5),"Enter review") -> Enter review | AB16: =HYPERLINK("#'MCDM_Checks'!A"&(MATCH("DS-011",MCDM_Checks!$B$6:$B$3733,0)+5),"Check evidence") -> Check evidence | AC16: Other official / repository; GitHub | AD16: https://dataverse.harvard.edu/dataset.xhtml?persistentId=doi:10.7910/DVN/EGIEBY&version=4.0 | AE16: https://arxiv.org/abs/2208.13054 | AF16: Compared_All_Platforms_TH_v3.0.xlsx!All_Datasets row 12 (DS-011)
A17: DS-012 | B17: CrackTrans (pavement crack dataset with complex backgrounds) | D17: Labeled-16 | E17: =INDEX(MCDM_Grades!$E$6:$E$238,MATCH(A17,MCDM_Grades!$A$6:$A$238,0)) -> 44.444444 | F17: =INDEX(MCDM_Grades!$F$6:$F$238,MATCH(A17,MCDM_Grades!$A$6:$A$238,0)) -> 100 | G17: =INDEX(MCDM_Grades!$G$6:$G$238,MATCH(A17,MCDM_Grades!$A$6:$A$238,0)) -> 0.44444444 | H17: =HYPERLINK("https://github.com/JZhongUTK/Pavement-crack-dataset","Dataset") -> Dataset | I17: =HYPERLINK("https://github.com/JZhongUTK/Pavement-crack-dataset","Evidence / paper") -> Evidence / paper | J17: v1 | K17: Semantic segmentation;Data augmentation research | L17: Images/frames as reported | M17: Smartphone | N17: Pixel-level crack ground truth | O17: Ground-truth masks | P17: NR ('released for public use' per README) | Q17: Direct_Download | R17: 455 | S17: Road environment: Pavements incl. shadow, wet, night, and grooved surfaces | U17: Small dataset (455 images); collection location not stated; Google Drive hosting (link liveness not independently re-tested) | V17: DS-012 | W17: Retained existing record | Z17: v3 evidence snapshot | AA17: =HYPERLINK("#'Manual_Review'!A"&(MATCH("DS-012",Manual_Review!$A$6:$A$238,0)+5),"Enter review") -> Enter review | AB17: =HYPERLINK("#'MCDM_Checks'!A"&(MATCH("DS-012",MCDM_Checks!$B$6:$B$3733,0)+5),"Check evidence") -> Check evidence | AC17: GitHub | AD17: https://github.com/JZhongUTK/Pavement-crack-dataset | AE17: https://github.com/JZhongUTK/Pavement-crack-dataset | AF17: Compared_All_Platforms_TH_v3.0.xlsx!All_Datasets row 13 (DS-012)
A18: DS-013 | B18: CrackTree260 | D18: Labeled-16 | E18: =INDEX(MCDM_Grades!$E$6:$E$238,MATCH(A18,MCDM_Grades!$A$6:$A$238,0)) -> 61.111111 | F18: =INDEX(MCDM_Grades!$F$6:$F$238,MATCH(A18,MCDM_Grades!$A$6:$A$238,0)) -> 100 | G18: =INDEX(MCDM_Grades!$G$6:$G$238,MATCH(A18,MCDM_Grades!$A$6:$A$238,0)) -> 0.61111111 | H18: =HYPERLINK("https://github.com/qinnzou/DeepCrack","Dataset") -> Dataset | I18: =HYPERLINK("https://github.com/qinnzou/DeepCrack","Evidence / paper") -> Evidence / paper | J18: CrackTree260 | K18: semantic segmentation; crack detection | L18: Images/frames as reported | M18: Visible-light area-array camera | N18: crack pixel mask | O18: Image-mask pairs | P18: NR | Q18: Direct_Download | R18: 260 | S18: Road environment: Road pavement | U18: Small, crack-only dataset; location, license, and detailed environmental metadata are not reported. | V18: DS-013 | W18: Retained existing record | X18: Shared host; distinct data (DS-009, DS-013, DS-014) | Z18: v3 evidence snapshot | AA18: =HYPERLINK("#'Manual_Review'!A"&(MATCH("DS-013",Manual_Review!$A$6:$A$238,0)+5),"Enter review") -> Enter review | AB18: =HYPERLINK("#'MCDM_Checks'!A"&(MATCH("DS-013",MCDM_Checks!$B$6:$B$3733,0)+5),"Check evidence") -> Check evidence | AC18: GitHub | AD18: https://github.com/qinnzou/DeepCrack | AE18: https://github.com/qinnzou/DeepCrack | AF18: Compared_All_Platforms_TH_v3.0.xlsx!All_Datasets row 14 (DS-013)
A19: DS-014 | B19: CRKWH100 | D19: Labeled-16 | E19: =INDEX(MCDM_Grades!$E$6:$E$238,MATCH(A19,MCDM_Grades!$A$6:$A$238,0)) -> 50 | F19: =INDEX(MCDM_Grades!$F$6:$F$238,MATCH(A19,MCDM_Grades!$A$6:$A$238,0)) -> 100 | G19: =INDEX(MCDM_Grades!$G$6:$G$238,MATCH(A19,MCDM_Grades!$A$6:$A$238,0)) -> 0.5 | H19: =HYPERLINK("https://github.com/qinnzou/DeepCrack","Dataset") -> Dataset | I19: =HYPERLINK("https://github.com/qinnzou/DeepCrack","Evidence / paper") -> Evidence / paper | J19: CRKWH100 | K19: semantic segmentation; crack detection | L19: Images/frames as reported | M19: Visible-light line-array camera | N19: crack pixel mask | O19: Image-mask pairs | P19: NR | Q19: Direct_Download | R19: 100 | S19: Road environment: Road pavement | U19: Very small crack-only dataset; 1 mm ground sampling distance is reported, but pixel resolution, navigation, location, license, and environmental metadata are not reported. | V19: DS-014 | W19: Retained existing record | X19: Shared host; distinct data (DS-009, DS-013, DS-014) | Z19: v3 evidence snapshot | AA19: =HYPERLINK("#'Manual_Review'!A"&(MATCH("DS-014",Manual_Review!$A$6:$A$238,0)+5),"Enter review") -> Enter review | AB19: =HYPERLINK("#'MCDM_Checks'!A"&(MATCH("DS-014",MCDM_Checks!$B$6:$B$3733,0)+5),"Check evidence") -> Check evidence | AC19: GitHub | AD19: https://github.com/qinnzou/DeepCrack | AE19: https://github.com/qinnzou/DeepCrack | AF19: Compared_All_Platforms_TH_v3.0.xlsx!All_Datasets row 15 (DS-014)
A20: DS-015 | B20: CUBIT-Det | D20: Labeled-16 | E20: =INDEX(MCDM_Grades!$E$6:$E$238,MATCH(A20,MCDM_Grades!$A$6:$A$238,0)) -> 77.777778 | F20: =INDEX(MCDM_Grades!$F$6:$F$238,MATCH(A20,MCDM_Grades!$A$6:$A$238,0)) -> 100 | G20: =INDEX(MCDM_Grades!$G$6:$G$238,MATCH(A20,MCDM_Grades!$A$6:$A$238,0)) -> 0.77777778 | H20: =HYPERLINK("https://github.com/CUHK-USR-Group/Defect-Dataset","Dataset") -> Dataset | I20: =HYPERLINK("https://github.com/CUHK-USR-Group/Defect-Dataset","Evidence / paper") -> Evidence / paper | J20: 2024 | K20: defect detection; UAV infrastructure inspection | L20: Images/frames as reported | M20: UAV onboard cameras | N20: crack; spalling; moisture; building; pavement; bridge | O20: bounding boxes | P20: NR | Q20: Registration | R20: 5527 | S20: China; Hong Kong; Road environment: Mixed infrastructure; pavement subset | U20: Only 29% pavement; mixed defect/infrastructure taxonomy; access code required | V20: DS-015 | W20: Retained existing record | Z20: v3 evidence snapshot | AA20: =HYPERLINK("#'Manual_Review'!A"&(MATCH("DS-015",Manual_Review!$A$6:$A$238,0)+5),"Enter review") -> Enter review | AB20: =HYPERLINK("#'MCDM_Checks'!A"&(MATCH("DS-015",MCDM_Checks!$B$6:$B$3733,0)+5),"Check evidence") -> Check evidence | AC20: GitHub | AD20: https://github.com/CUHK-USR-Group/Defect-Dataset | AE20: https://github.com/CUHK-USR-Group/Defect-Dataset | AF20: Compared_All_Platforms_TH_v3.0.xlsx!All_Datasets row 16 (DS-015)
A21: DS-016 | B21: DeepCrack-537 | D21: Labeled-16 | E21: =INDEX(MCDM_Grades!$E$6:$E$238,MATCH(A21,MCDM_Grades!$A$6:$A$238,0)) -> 61.111111 | F21: =INDEX(MCDM_Grades!$F$6:$F$238,MATCH(A21,MCDM_Grades!$A$6:$A$238,0)) -> 100 | G21: =INDEX(MCDM_Grades!$G$6:$G$238,MATCH(A21,MCDM_Grades!$A$6:$A$238,0)) -> 0.61111111 | H21: =HYPERLINK("https://github.com/yhlleo/DeepCrack","Dataset") -> Dataset | I21: =HYPERLINK("https://github.com/yhlleo/DeepCrack","Evidence / paper") -> Evidence / paper | J21: 537-image benchmark | K21: semantic segmentation; crack detection | L21: Images/frames as reported | M21: Mixed cameras | N21: crack pixel mask | O21: Image-mask pairs | P21: NR | Q21: Direct_Download | R21: 537 | S21: Road environment: Roadway; mixed crack scenes | U21: Contains mixed crack scenes/materials rather than a strictly pavement-only corpus; noncommercial-use restriction. | V21: DS-016 | W21: Retained existing record | X21: Compiled crack ancestry (DS-007, DS-008, DS-011, DS-016, DS-142) | Z21: v3 evidence snapshot | AA21: =HYPERLINK("#'Manual_Review'!A"&(MATCH("DS-016",Manual_Review!$A$6:$A$238,0)+5),"Enter review") -> Enter review | AB21: =HYPERLINK("#'MCDM_Checks'!A"&(MATCH("DS-016",MCDM_Checks!$B$6:$B$3733,0)+5),"Check evidence") -> Check evidence | AC21: GitHub | AD21: https://github.com/yhlleo/DeepCrack | AE21: https://github.com/yhlleo/DeepCrack | AF21: Compared_All_Platforms_TH_v3.0.xlsx!All_Datasets row 17 (DS-016)
A22: DS-017 | B22: EdmCrack600 | D22: Labeled-16 | E22: =INDEX(MCDM_Grades!$E$6:$E$238,MATCH(A22,MCDM_Grades!$A$6:$A$238,0)) -> 44.444444 | F22: =INDEX(MCDM_Grades!$F$6:$F$238,MATCH(A22,MCDM_Grades!$A$6:$A$238,0)) -> 100 | G22: =INDEX(MCDM_Grades!$G$6:$G$238,MATCH(A22,MCDM_Grades!$A$6:$A$238,0)) -> 0.44444444 | H22: =HYPERLINK("https://github.com/mqp2259/EdmCrack600","Dataset") -> Dataset | I22: =HYPERLINK("https://github.com/mqp2259/EdmCrack600","Evidence / paper") -> Evidence / paper | J22: 2020; EdmCrack600 | K22: Distress / roughness | L22: Images / patches | M22: Other / mixed capture | N22: Crack/background. | O22: Pixel-level masks | P22: Academic use; commercial use prohibited by authors. | Q22: Public links | R22: 600 images | S22: Edmonton, Canada | T22: Qipei Mei, Mustafa Gül and collaborators | U22: Useful supplemental crack segmentation set; also partly reused by Pothole Mix. Do not interpret as verified AV footage. | V22: DS-017; D024 | W22: Same release | Z22: AV inventory evidence snapshot | AA22: =HYPERLINK("#'Manual_Review'!A"&(MATCH("DS-017",Manual_Review!$A$6:$A$238,0)+5),"Enter review") -> Enter review | AB22: =HYPERLINK("#'MCDM_Checks'!A"&(MATCH("DS-017",MCDM_Checks!$B$6:$B$3733,0)+5),"Check evidence") -> Check evidence | AC22: GitHub | AD22: https://github.com/mqp2259/EdmCrack600 | AE22: https://github.com/mqp2259/EdmCrack600 | AF22: Compared_All_Platforms_TH_v3.0.xlsx!All_Datasets row 18 (DS-017); AV_Pavement_Dataset_Inventory.xlsx!Datasets row 30 (D024)
A23: DS-018 | B23: GAPs384 | D23: Labeled-16 | E23: =INDEX(MCDM_Grades!$E$6:$E$238,MATCH(A23,MCDM_Grades!$A$6:$A$238,0)) -> 75 | F23: =INDEX(MCDM_Grades!$F$6:$F$238,MATCH(A23,MCDM_Grades!$A$6:$A$238,0)) -> 100 | G23: =INDEX(MCDM_Grades!$G$6:$G$238,MATCH(A23,MCDM_Grades!$A$6:$A$238,0)) -> 0.75 | H23: =HYPERLINK("https://github.com/fyangneil/pavement-crack-detection","Dataset") -> Dataset | I23: =HYPERLINK("https://github.com/fyangneil/pavement-crack-detection","Evidence / paper") -> Evidence / paper | J23: 384-image pixel-annotated subset [GPT] | GAPs384 [Test_Batch] | K23: crack segmentation [GPT] | semantic segmentation; crack detection [Test_Batch] | L23: Images/frames as reported | M23: Professional pavement inspection imagery derived from GAPs [GPT] | Road inspection camera [Test_Batch] | N23: crack pixels; background pixels [GPT] | crack pixel mask [Test_Batch] | O23: pixel masks | P23: NR | Q23: Direct_Download | R23: 384 | S23: Germany; Road environment: Asphalt pavement [GPT] | Roadway [Test_Batch] | U23: Small crack-only subset; limited geographic and collection metadata [GPT] | Small crack-only benchmark; license, detailed weather, and vehicle metadata are not clearly documented. [Test_Batch] | V23: DS-018 | W23: Retained existing record | X23: Shared host; distinct data (DS-007, DS-018); GAPs family; distinct releases (DS-018, DS-193, DS-194) | Z23: v3 evidence snapshot | AA23: =HYPERLINK("#'Manual_Review'!A"&(MATCH("DS-018",Manual_Review!$A$6:$A$238,0)+5),"Enter review") -> Enter review | AB23: =HYPERLINK("#'MCDM_Checks'!A"&(MATCH("DS-018",MCDM_Checks!$B$6:$B$3733,0)+5),"Check evidence") -> Check evidence | AC23: GitHub | AD23: https://github.com/fyangneil/pavement-crack-detection | AE23: https://github.com/fyangneil/pavement-crack-detection | AF23: Compared_All_Platforms_TH_v3.0.xlsx!All_Datasets row 19 (DS-018)
A24: DS-019 | B24: GeoPave-DroneSet (UAV pavement distress dataset, DronePave-DfineX) | D24: Labeled-16 | E24: =INDEX(MCDM_Grades!$E$6:$E$238,MATCH(A24,MCDM_Grades!$A$6:$A$238,0)) -> 16.666667 | F24: =INDEX(MCDM_Grades!$F$6:$F$238,MATCH(A24,MCDM_Grades!$A$6:$A$238,0)) -> 94.444444 | G24: =INDEX(MCDM_Grades!$G$6:$G$238,MATCH(A24,MCDM_Grades!$A$6:$A$238,0)) -> 0.22222222 | H24: =HYPERLINK("https://github.com/chenxiang-web/DronePave-DfineX","Dataset") -> Dataset | I24: =HYPERLINK("https://github.com/chenxiang-web/DronePave-DfineX","Evidence / paper") -> Evidence / paper | J24: Partial preview (full release pending paper acceptance) | K24: Object detection | L24: NR | M24: UAV (full-resolution imagery) | N24: Annotated atop full-resolution images (details NR) | O24: NR | P24: NR | Q24: Metadata_Only | R24: NR | S24: Road environment: Pavements with complex backgrounds (UAV inspection) | U24: Complete dataset to be released only after paper acceptance; only sample images available; re-check for release | V24: DS-019 | W24: Retained existing record | Z24: v3 evidence snapshot | AA24: =HYPERLINK("#'Manual_Review'!A"&(MATCH("DS-019",Manual_Review!$A$6:$A$238,0)+5),"Enter review") -> Enter review | AB24: =HYPERLINK("#'MCDM_Checks'!A"&(MATCH("DS-019",MCDM_Checks!$B$6:$B$3733,0)+5),"Check evidence") -> Check evidence | AC24: GitHub | AD24: https://github.com/chenxiang-web/DronePave-DfineX | AE24: https://github.com/chenxiang-web/DronePave-DfineX | AF24: Compared_All_Platforms_TH_v3.0.xlsx!All_Datasets row 20 (DS-019)
A25: DS-020 | B25: Highway Crack and Sealed-Crack Dataset (CHDyshli) | D25: Labeled-16 | E25: =INDEX(MCDM_Grades!$E$6:$E$238,MATCH(A25,MCDM_Grades!$A$6:$A$238,0)) -> 52.777778 | F25: =INDEX(MCDM_Grades!$F$6:$F$238,MATCH(A25,MCDM_Grades!$A$6:$A$238,0)) -> 100 | G25: =INDEX(MCDM_Grades!$G$6:$G$238,MATCH(A25,MCDM_Grades!$A$6:$A$238,0)) -> 0.52777778 | H25: =HYPERLINK("https://github.com/CHDyshli/PavementCrackDetection","Dataset") -> Dataset | I25: =HYPERLINK("https://github.com/CHDyshli/PavementCrackDetection","Evidence / paper") -> Evidence / paper | J25: NR | K25: object detection | L25: Images/frames as reported | M25: Highway condition monitoring vehicle [GPT] | Highway pavement-condition monitoring vehicle [Test_Batch] | N25: crack; sealed crack | O25: NR | P25: NR | Q25: Direct_Download | R25: 10400 | S25: China; Road environment: Highway asphalt pavement [GPT] | Highway [Test_Batch] | U25: Only two target classes; license, geography, resolution, and collection dates not reported in README [GPT] | Release year, geography, image resolution, license, and annotation format are unresolved despite strong reported scale. [Test_Batch] | V25: DS-020 | W25: Retained existing record | Z25: v3 evidence snapshot | AA25: =HYPERLINK("#'Manual_Review'!A"&(MATCH("DS-020",Manual_Review!$A$6:$A$238,0)+5),"Enter review") -> Enter review | AB25: =HYPERLINK("#'MCDM_Checks'!A"&(MATCH("DS-020",MCDM_Checks!$B$6:$B$3733,0)+5),"Check evidence") -> Check evidence | AC25: GitHub | AD25: https://github.com/CHDyshli/PavementCrackDetection | AE25: https://github.com/CHDyshli/PavementCrackDetection | AF25: Compared_All_Platforms_TH_v3.0.xlsx!All_Datasets row 21 (DS-020)
A26: DS-021 | B26: IRRDD (Iran Road Damage Dataset) | D26: Labeled-16 | E26: =INDEX(MCDM_Grades!$E$6:$E$238,MATCH(A26,MCDM_Grades!$A$6:$A$238,0)) -> 47.222222 | F26: =INDEX(MCDM_Grades!$F$6:$F$238,MATCH(A26,MCDM_Grades!$A$6:$A$238,0)) -> 100 | G26: =INDEX(MCDM_Grades!$G$6:$G$238,MATCH(A26,MCDM_Grades!$A$6:$A$238,0)) -> 0.47222222 | H26: =HYPERLINK("https://github.com/IranRoadDamageDataset/IRRDD","Dataset") -> Dataset | I26: =HYPERLINK("https://github.com/IranRoadDamageDataset/IRRDD","Evidence / paper") -> Evidence / paper | J26: 2022 release | K26: Object detection | L26: Images/frames as reported | M26: NR | N26: RDD-style four-class taxonomy (D00/D10/D20/D40) | O26: YOLO txt | P26: NR | Q26: Direct_Download | R26: 25000 | S26: Iran; Road environment: Public roads | U26: No associated peer-reviewed data paper identified; collection platform and QC undocumented; 6-part Google Drive hosting (link liveness not independently re-tested) | V26: DS-021 | W26: Retained existing record | Z26: v3 evidence snapshot | AA26: =HYPERLINK("#'Manual_Review'!A"&(MATCH("DS-021",Manual_Review!$A$6:$A$238,0)+5),"Enter review") -> Enter review | AB26: =HYPERLINK("#'MCDM_Checks'!A"&(MATCH("DS-021",MCDM_Checks!$B$6:$B$3733,0)+5),"Check evidence") -> Check evidence | AC26: GitHub | AD26: https://github.com/IranRoadDamageDataset/IRRDD | AE26: https://github.com/IranRoadDamageDataset/IRRDD | AF26: Compared_All_Platforms_TH_v3.0.xlsx!All_Datasets row 22 (DS-021)
A27: DS-022 | B27: IRT Asphalt Pavement Crack Segmentation Dataset (RGB + Infrared + Fusion) | D27: Labeled-16 | E27: =INDEX(MCDM_Grades!$E$6:$E$238,MATCH(A27,MCDM_Grades!$A$6:$A$238,0)) -> 75 | F27: =INDEX(MCDM_Grades!$F$6:$F$238,MATCH(A27,MCDM_Grades!$A$6:$A$238,0)) -> 100 | G27: =INDEX(MCDM_Grades!$G$6:$G$238,MATCH(A27,MCDM_Grades!$A$6:$A$238,0)) -> 0.75 | H27: =HYPERLINK("https://github.com/lfangyu09/IR-Crack-detection","Dataset") -> Dataset | I27: =HYPERLINK("https://github.com/lfangyu09/IR-Crack-detection","Evidence / paper") -> Evidence / paper | J27: Zenodo record 11624965 [Claude] | v1 [CodeX] | K27: Semantic segmentation;RGB-T multimodal fusion [Claude] | Semantic_Segmentation;Multimodal_Fusion [Claude] | Semantic segmentation [CodeX] | multimodal semantic segmentation; crack detection [Test_Batch] | L27: Images/frames as reported | M27: Infrared thermography camera (visible + infrared + IR-Fusion imagery) [Claude] | Vehicle_Mounted_Camera [Claude] | Visible camera; Infrared thermography [CodeX] | Aligned visible and infrared camera system [Test_Batch] | N27: Manually annotated crack ground truth (Photoshop) [Claude] | Binary ground-truth images (crack vs background) paired with visible, infrared and 50 percent fusion imagery [Claude] | Binary ground truth masks [CodeX] | crack pixel mask [Test_Batch] | O27: Ground-truth mask images [Claude] | Binary_Image_Mask [Claude] | ZIP; Binary images [CodeX] | Aligned RGB; thermal infrared; pixel masks [Test_Batch] | P27: NR (Zenodo record license not re-verified in this batch) [Claude] | CC-BY-4.0 [Claude] | Creative Commons Attribution 4.0 International [CodeX] | Q27: Direct_Download [Claude/CodeX] | UNK [Test_Batch] | R27: 448 [Claude] | 369 [CodeX] | S27: United States; Road environment: Asphalt pavements; clean and rough, light and dark backgrounds; three periods in one day [Claude] | Asphalt pavement [CodeX] | Roadway [Test_Batch] | U27: 448 image sets (small); acquisition location not stated; Release_Year taken from associated T-ITS paper year (Zenodo deposit 2024, not separately versioned here) [Claude] | Image count, resolution and collection geography not reported in the Zenodo record; single distress class (crack); performance figures live in the journal article rather than the data record [Claude] | Image count, resolution, site, and explicit QA process are not reported on the Zenodo record. [CodeX] | Dataset identity, data-access route, count, license, and collection geography require resolution beyond the model repository. [Test_Batch] | V27: DS-022 | W27: Retained existing record | X27: Related infrared dataset releases (DS-022, DS-023, DS-113, DS-114) | Z27: v3 evidence snapshot | AA27: =HYPERLINK("#'Manual_Review'!A"&(MATCH("DS-022",Manual_Review!$A$6:$A$238,0)+5),"Enter review") -> Enter review | AB27: =HYPERLINK("#'MCDM_Checks'!A"&(MATCH("DS-022",MCDM_Checks!$B$6:$B$3733,0)+5),"Check evidence") -> Check evidence | AC27: GitHub; Zenodo | AD27: https://github.com/lfangyu09/IR-Crack-detection | AE27: https://github.com/lfangyu09/IR-Crack-detection | AF27: Compared_All_Platforms_TH_v3.0.xlsx!All_Datasets row 23 (DS-022)
A28: DS-023 | B28: IRT Multiple-Type Pavement Distress Detection Dataset (Infrared Thermography) | D28: Labeled-16 | E28: =INDEX(MCDM_Grades!$E$6:$E$238,MATCH(A28,MCDM_Grades!$A$6:$A$238,0)) -> 36.111111 | F28: =INDEX(MCDM_Grades!$F$6:$F$238,MATCH(A28,MCDM_Grades!$A$6:$A$238,0)) -> 100 | G28: =INDEX(MCDM_Grades!$G$6:$G$238,MATCH(A28,MCDM_Grades!$A$6:$A$238,0)) -> 0.36111111 | H28: =HYPERLINK("https://github.com/lfangyu09/IR-Crack-detection","Dataset") -> Dataset | I28: =HYPERLINK("https://github.com/lfangyu09/IR-Crack-detection","Evidence / paper") -> Evidence / paper | J28: Zenodo record 11638443 | K28: Object detection;Multimodal (RGB + thermal) learning [Claude] | Object_Detection;Multimodal_Fusion [Claude] | L28: NR | M28: Infrared thermography camera (visible + infrared imagery) [Claude] | Vehicle_Mounted_Camera [Claude] | N28: Multi-type distress detection labels [Claude] | PASCAL VOC object classes across visible, infrared and three visible/infrared fusion levels (25/50/75 percent IRT) [Claude] | O28: PASCAL_VOC_XML | P28: NR (Zenodo record license not re-verified in this batch) [Claude] | CC-BY-4.0 [Claude] | Q28: Direct_Download | R28: NR | S28: United States; Road environment: Asphalt concrete pavement | U28: Image count, class list, and format not stated in README (NR); niche thermographic modality [Claude] | Image count, resolution and collection geography not reported in the Zenodo record; class list not enumerated on the landing page; performance figures live in the journal article rather than the data record [Claude] | V28: DS-023 | W28: Retained existing record | X28: Related infrared dataset releases (DS-022, DS-023, DS-113, DS-114) | Z28: v3 evidence snapshot | AA28: =HYPERLINK("#'Manual_Review'!A"&(MATCH("DS-023",Manual_Review!$A$6:$A$238,0)+5),"Enter review") -> Enter review | AB28: =HYPERLINK("#'MCDM_Checks'!A"&(MATCH("DS-023",MCDM_Checks!$B$6:$B$3733,0)+5),"Check evidence") -> Check evidence | AC28: GitHub; Zenodo | AD28: https://github.com/lfangyu09/IR-Crack-detection | AE28: https://github.com/lfangyu09/IR-Crack-detection | AF28: Compared_All_Platforms_TH_v3.0.xlsx!All_Datasets row 24 (DS-023)
A29: DS-024 | B29: Kansas City LCMS Pavement Distress Dataset (Image2PCI) | D29: Labeled-16 | E29: =INDEX(MCDM_Grades!$E$6:$E$238,MATCH(A29,MCDM_Grades!$A$6:$A$238,0)) -> 38.888889 | F29: =INDEX(MCDM_Grades!$F$6:$F$238,MATCH(A29,MCDM_Grades!$A$6:$A$238,0)) -> 100 | G29: =INDEX(MCDM_Grades!$G$6:$G$238,MATCH(A29,MCDM_Grades!$A$6:$A$238,0)) -> 0.38888889 | H29: =HYPERLINK("https://github.com/neemajakisa/Pavement-Distress-Dataset","Dataset") -> Dataset | I29: =HYPERLINK("https://github.com/neemajakisa/Pavement-Distress-Dataset","Evidence / paper") -> Evidence / paper | J29: v1 | K29: Segmentation;PCI estimation model training/benchmarking [Claude] | instance segmentation; distress classification; severity estimation; PCI prediction [GPT] | instance segmentation; PCI estimation [Test_Batch] | L29: NR | M29: Laser Crack Measurement System (LCMS) survey vehicle [Claude] | Laser Crack Measurement System inspection vehicle [GPT] | LCMS pavement survey vehicle [Test_Batch] | N29: Polygon annotations combining crack type and severity (PCI-aligned) [Claude] | distress type; severity [GPT] | distress type; distress severity [Test_Batch] | O29: JSON annotation files [Claude] | JSON polygon annotations [GPT/Test_Batch] | P29: NR | Q29: Direct_Download | R29: NR | S29: United States; Kansas City, Missouri; Road environment: Public roads (top-down pavement surface views) [Claude] | Urban roadway [GPT] | Urban [Test_Batch] | U29: Image count not reported in README (NR); LCMS imagery differs from CAV camera viewpoint; Google Drive folder hosting (link liveness not independently re-tested) [Claude] | Image count, image resolution, license, and collection dates not reported on the repository landing page [GPT] | Image count, formal license, collection dates, and explicit PCI ground-truth fields are not reported in the README. [Test_Batch] | V29: DS-024 | W29: Retained existing record | Z29: v3 evidence snapshot | AA29: =HYPERLINK("#'Manual_Review'!A"&(MATCH("DS-024",Manual_Review!$A$6:$A$238,0)+5),"Enter review") -> Enter review | AB29: =HYPERLINK("#'MCDM_Checks'!A"&(MATCH("DS-024",MCDM_Checks!$B$6:$B$3733,0)+5),"Check evidence") -> Check evidence | AC29: GitHub | AD29: https://github.com/neemajakisa/Pavement-Distress-Dataset | AE29: https://github.com/neemajakisa/Pavement-Distress-Dataset | AF29: Compared_All_Platforms_TH_v3.0.xlsx!All_Datasets row 25 (DS-024)
A30: DS-025 | B30: LEiS pavement crack image dataset | D30: Labeled-16 | E30: =INDEX(MCDM_Grades!$E$6:$E$238,MATCH(A30,MCDM_Grades!$A$6:$A$238,0)) -> 11.111111 | F30: =INDEX(MCDM_Grades!$F$6:$F$238,MATCH(A30,MCDM_Grades!$A$6:$A$238,0)) -> 100 | G30: =INDEX(MCDM_Grades!$G$6:$G$238,MATCH(A30,MCDM_Grades!$A$6:$A$238,0)) -> 0.11111111 | H30: =HYPERLINK("https://github.com/DrEdwardLee/Pavement-Crack-Dataset","Dataset") -> Dataset | I30: =HYPERLINK("https://github.com/DrEdwardLee/Pavement-Crack-Dataset","Evidence / paper") -> Evidence / paper | J30: v1 (in-repo rar archive) | K30: Crack detection (per repo description) | L30: NR | M30: NR | N30: UNK (no README; annotation presence not verifiable from file listing) | O30: NR | P30: NR | Q30: Direct_Download | R30: NR | S30: Road environment: Pavements | U30: No README or documentation; annotations, counts, provenance, and license all unverified (data stored as LEiS-Data.rar in repo) | V30: DS-025 | W30: Retained existing record | X30: Same acquisition lineage; different archives/releases (DS-003, DS-025, DS-090) | Z30: v3 evidence snapshot | AA30: =HYPERLINK("#'Manual_Review'!A"&(MATCH("DS-025",Manual_Review!$A$6:$A$238,0)+5),"Enter review") -> Enter review | AB30: =HYPERLINK("#'MCDM_Checks'!A"&(MATCH("DS-025",MCDM_Checks!$B$6:$B$3733,0)+5),"Check evidence") -> Check evidence | AC30: GitHub | AD30: https://github.com/DrEdwardLee/Pavement-Crack-Dataset | AE30: https://github.com/DrEdwardLee/Pavement-Crack-Dataset | AF30: Compared_All_Platforms_TH_v3.0.xlsx!All_Datasets row 26 (DS-025)
